Workbook

Sheet Chart 1 - Graph
B2: Columbus Verification Status Summary | AP2: 42138
B3: No. | C3: IP | D3: RTL Designer | E3: Verification Engineer | G3: RTL Sim. | V3: FPGA | AB3: POST Sim. | AH3: ASIC | AN3: Last Updated | AR3: Remark / Coverage Waive
G4: F1 | I4: F2 | K4: F3 | M4: F1~3 | N4: Cov. SoC (F2,F3) | O4: Cov. S.A (F0,F1) | P4: Done | S4: Prog. | V4: Cases | W4: Pass | X4: Prog. | Z4: Done | AB4: Cases | AC4: Pass | AD4: Prog. | AE4: Done | AH4: Cases | AI4: Pass | AJ4: Prog. | AL4: Done | AN4: Date | AO4: RTL | AP4: FPGA | AQ4: ASIC
C5: IP | G5: Cases | H5: Pass | I5: Cases | J5: Pass | K5: Cases | L5: Pass | M5: Prog. | Q5: RTL Case | R5: RTL Pass | S5: % | T5: RTL | V5: FPGA Case | W5: FPGA Pass | X5: % | Y5: FPGA | AB5: Sim. Case | AC5: Sim. Pass | AF5: POST Sim. | AH5: ASIC Case | AI5: ASIC Pass | AK5: ASIC
B6: 1 | C6: =[1]Summary!$B$7 -> Cortex-M3 | D6: =[1]Summary!$C$7 -> 최호윤 수석 | E6: =[1]Summary!$D$7 -> 조성엽 책임 | G6: 10 | H6: 10 | I6: 12 | J6: 5 | K6: =[1]Summary!$I$7 -> 0 | L6: =[1]Summary!$J$7 -> 0 | M6: =[1]Summary!$K$7 -> - | N6: =[1]Summary!$L$7 -> 0 | O6: =[1]Summary!$M$7 -> 0 | P6: =[1]Summary!$N$7 -> - | Q6: =G6+I6+K6 -> 22 | R6: =H6+J6+L6 -> 15 | S6: =R6/Q6 -> 0.68181818 | V6: 30 | W6: 26 | X6: =W6/V6 -> 0.86666667 | Z6: =[1]Summary!$R$7 -> - | AB6: 20 | AC6: 10 | AD6: =AC6/AB6 -> 0.5 | AE6: =[1]Summary!$V$7 -> - | AH6: 20 | AI6: 5 | AJ6: =AI6/AH6 -> 0.25 | AL6: =[1]Summary!$Z$7 -> - | AN6: =[1]Summary!$AA$7 -> 42138 | AO6: =[1]Summary!$AB$7 -> ? | AP6: =[1]Summary!$AC$7 -> ? | AQ6: =[1]Summary!$AD$7 -> ? | AR6: =[1]Summary!$AE$7 -> RTL: POST: FPGA:
B7: 2 | C7: =[2]Summary!$B$7 -> HCT | D7: =[2]Summary!$C$7 -> 이원규 선임 | E7: =[2]Summary!$D$7 -> 박재우 책임 | G7: 15 | H7: 5 | I7: 12 | J7: 5 | K7: =[2]Summary!$I$7 -> 0 | L7: =[2]Summary!$J$7 -> 0 | M7: =[2]Summary!$K$7 -> - | N7: =[2]Summary!$L$7 -> 0 | O7: =[2]Summary!$M$7 -> 0 | P7: =[2]Summary!$N$7 -> - | Q7: =G7+I7+K7 -> 27 | R7: =H7+J7+L7 -> 10 | S7: =R7/Q7 -> 0.37037037 | V7: 40 | W7: 25 | X7: =W7/V7 -> 0.625 | Z7: =[2]Summary!$R$7 -> - | AB7: 30 | AC7: 20 | AD7: =AC7/AB7 -> 0.66666667 | AE7: =[2]Summary!$V$7 -> - | AH7: 30 | AI7: 2 | AJ7: =AI7/AH7 -> 0.066666667 | AL7: =[2]Summary!$Z$7 -> - | AN7: =[2]Summary!$AA$7 -> 42138 | AO7: =[2]Summary!$AB$7 -> ? | AP7: =[2]Summary!$AC$7 -> ? | AQ7: =[2]Summary!$AD$7 -> ? | AR7: =[2]Summary!$AE$7 -> RTL: POST: FPGA:
B8: 3 | C8: =[3]Summary!$B$7 -> FCT | D8: =[3]Summary!$C$7 -> 천동엽 책임 | E8: =[3]Summary!$D$7 -> 조성엽 책임 | G8: 20 | H8: 18 | I8: 20 | J8: 15 | K8: =[3]Summary!$I$7 -> 0 | L8: =[3]Summary!$J$7 -> 0 | M8: =[3]Summary!$K$7 -> - | N8: =[3]Summary!$L$7 -> 0 | O8: =[3]Summary!$M$7 -> 0 | P8: =[3]Summary!$N$7 -> - | Q8: =G8+I8+K8 -> 40 | R8: =H8+J8+L8 -> 33 | S8: =R8/Q8 -> 0.825 | V8: 30 | W8: 30 | X8: =W8/V8 -> 1 | Z8: =[3]Summary!$R$7 -> - | AB8: 30 | AC8: 25 | AD8: =AC8/AB8 -> 0.83333333 | AE8: =[3]Summary!$V$7 -> - | AH8: 30 | AI8: 3 | AJ8: =AI8/AH8 -> 0.1 | AL8: =[3]Summary!$Z$7 -> - | AN8: =[3]Summary!$AA$7 -> 42138 | AO8: =[3]Summary!$AB$7 -> ? | AP8: =[3]Summary!$AC$7 -> ? | AQ8: =[3]Summary!$AD$7 -> ? | AR8: =[3]Summary!$AE$7 -> RTL: POST: FPGA:
B9: 4 | C9: =[4]Summary!$B$7 -> Buffer Manager | D9: =[4]Summary!$C$7 -> 지대근 책임 | E9: =[4]Summary!$D$7 -> 조성엽 책임 | G9: 15 | H9: 10 | I9: 30 | J9: 20 | K9: =[4]Summary!$I$7 -> 0 | L9: =[4]Summary!$J$7 -> 0 | M9: =[4]Summary!$K$7 -> - | N9: =[4]Summary!$L$7 -> 0 | O9: =[4]Summary!$M$7 -> 0 | P9: =[4]Summary!$N$7 -> - | Q9: =G9+I9+K9 -> 45 | R9: =H9+J9+L9 -> 30 | S9: =R9/Q9 -> 0.66666667 | V9: 20 | W9: 20 | X9: =W9/V9 -> 1 | Z9: =[4]Summary!$R$7 -> - | AB9: 40 | AC9: 30 | AD9: =AC9/AB9 -> 0.75 | AE9: =[4]Summary!$V$7 -> - | AH9: 30 | AI9: 2 | AJ9: =AI9/AH9 -> 0.066666667 | AL9: =[4]Summary!$Z$7 -> - | AN9: =[4]Summary!$AA$7 -> 42138 | AO9: =[4]Summary!$AB$7 -> ? | AP9: =[4]Summary!$AC$7 -> ? | AQ9: =[4]Summary!$AD$7 -> ? | AR9: =[4]Summary!$AE$7 -> RTL: POST: FPGA:
B10: 5 | C10: =[5]Summary!$B$7 -> Search Engine | D10: =[5]Summary!$C$7 -> 김현욱 선임 | E10: =[5]Summary!$D$7 -> 김현욱 선임 | G10: 20 | H10: 16 | I10: 15 | J10: 10 | K10: =[5]Summary!$I$7 -> 0 | L10: =[5]Summary!$J$7 -> 0 | M10: =[5]Summary!$K$7 -> - | N10: =[5]Summary!$L$7 -> 0 | O10: =[5]Summary!$M$7 -> 0 | P10: =[5]Summary!$N$7 -> - | Q10: =G10+I10+K10 -> 35 | R10: =H10+J10+L10 -> 26 | S10: =R10/Q10 -> 0.74285714 | V10: 20 | W10: 20 | X10: =W10/V10 -> 1 | Z10: =[5]Summary!$R$7 -> - | AB10: 20 | AC10: 15 | AD10: =AC10/AB10 -> 0.75 | AE10: =[5]Summary!$V$7 -> - | AH10: 30 | AI10: 2 | AJ10: =AI10/AH10 -> 0.066666667 | AL10: =[5]Summary!$Z$7 -> - | AN10: =[5]Summary!$AA$7 -> 42138 | AO10: =[5]Summary!$AB$7 -> ? | AP10: =[5]Summary!$AC$7 -> ? | AQ10: =[5]Summary!$AD$7 -> ? | AR10: =[5]Summary!$AE$7 -> RTL: POST: FPGA:
B11: 6 | C11: =[6]Summary!$B$7 -> MTSE | D11: =[6]Summary!$C$7 -> 김현욱 선임 | E11: =[6]Summary!$D$7 -> 김현욱 선임 | G11: 15 | H11: 14 | I11: 20 | J11: 15 | K11: =[6]Summary!$I$7 -> 0 | L11: =[6]Summary!$J$7 -> 0 | M11: =[6]Summary!$K$7 -> - | N11: =[6]Summary!$L$7 -> 0 | O11: =[6]Summary!$M$7 -> 0 | P11: =[6]Summary!$N$7 -> - | Q11: =G11+I11+K11 -> 35 | R11: =H11+J11+L11 -> 29 | S11: =R11/Q11 -> 0.82857143 | V11: 30 | W11: 25 | X11: =W11/V11 -> 0.83333333 | Z11: =[6]Summary!$R$7 -> - | AB11: 20 | AC11: 15 | AD11: =AC11/AB11 -> 0.75 | AE11: =[6]Summary!$V$7 -> - | AH11: 30 | AI11: 4 | AJ11: =AI11/AH11 -> 0.13333333 | AL11: =[6]Summary!$Z$7 -> - | AN11: =[6]Summary!$AA$7 -> 42138 | AO11: =[6]Summary!$AB$7 -> ? | AP11: =[6]Summary!$AC$7 -> ? | AQ11: =[6]Summary!$AD$7 -> ? | AR11: =[6]Summary!$AE$7 -> RTL: POST: FPGA:
B12: 7 | C12: =[7]Summary!$B$7 -> System Memory | D12: =[7]Summary!$C$7 -> 김현욱 선임 | E12: =[7]Summary!$D$7 -> 김현욱 선임 | G12: 10 | H12: 8 | I12: 15 | J12: 12 | K12: =[7]Summary!$I$7 -> 0 | L12: =[7]Summary!$J$7 -> 0 | M12: =[7]Summary!$K$7 -> - | N12: =[7]Summary!$L$7 -> 0 | O12: =[7]Summary!$M$7 -> 0 | P12: =[7]Summary!$N$7 -> - | Q12: =G12+I12+K12 -> 25 | R12: =H12+J12+L12 -> 20 | S12: =R12/Q12 -> 0.8 | V12: 30 | W12: 20 | X12: =W12/V12 -> 0.66666667 | Z12: =[7]Summary!$R$7 -> - | AB12: 20 | AC12: 20 | AD12: =AC12/AB12 -> 1 | AE12: =[7]Summary!$V$7 -> - | AH12: 20 | AI12: 3 | AJ12: =AI12/AH12 -> 0.15 | AL12: =[7]Summary!$Z$7 -> - | AN12: =[7]Summary!$AA$7 -> 42138 | AO12: =[7]Summary!$AB$7 -> ? | AP12: =[7]Summary!$AC$7 -> ? | AQ12: =[7]Summary!$AD$7 -> ? | AR12: =[7]Summary!$AE$7 -> RTL: POST: FPGA:
B13: 8 | C13: =[8]Summary!$B$7 -> Data Buffer | D13: =[8]Summary!$C$7 -> 김현욱 선임 | E13: =[8]Summary!$D$7 -> 김현욱 선임 | G13: 8 | H13: 8 | I13: 18 | J13: 15 | K13: =[8]Summary!$I$7 -> 0 | L13: =[8]Summary!$J$7 -> 0 | M13: =[8]Summary!$K$7 -> - | N13: =[8]Summary!$L$7 -> 0 | O13: =[8]Summary!$M$7 -> 0 | P13: =[8]Summary!$N$7 -> - | Q13: =G13+I13+K13 -> 26 | R13: =H13+J13+L13 -> 23 | S13: =R13/Q13 -> 0.88461538 | V13: 40 | W13: 35 | X13: =W13/V13 -> 0.875 | Z13: =[8]Summary!$R$7 -> - | AB13: 20 | AC13: 18 | AD13: =AC13/AB13 -> 0.9 | AE13: =[8]Summary!$V$7 -> - | AH13: 20 | AI13: 4 | AJ13: =AI13/AH13 -> 0.2 | AL13: =[8]Summary!$Z$7 -> - | AN13: =[8]Summary!$AA$7 -> 42138 | AO13: =[8]Summary!$AB$7 -> ? | AP13: =[8]Summary!$AC$7 -> ? | AQ13: =[8]Summary!$AD$7 -> ? | AR13: =[8]Summary!$AE$7 -> RTL: POST: FPGA:
B14: 9 | C14: =[9]Summary!$B$7 -> DMA | D14: =[9]Summary!$C$7 -> 김현욱 선임 | E14: =[9]Summary!$D$7 -> 김현욱 선임 | G14: 9 | H14: 8 | I14: 30 | J14: 20 | K14: =[9]Summary!$I$7 -> 0 | L14: =[9]Summary!$J$7 -> 0 | M14: =[9]Summary!$K$7 -> - | N14: =[9]Summary!$L$7 -> 0 | O14: =[9]Summary!$M$7 -> 0 | P14: =[9]Summary!$N$7 -> - | Q14: =G14+I14+K14 -> 39 | R14: =H14+J14+L14 -> 28 | S14: =R14/Q14 -> 0.71794872 | V14: 50 | W14: 40 | X14: =W14/V14 -> 0.8 | Z14: =[9]Summary!$R$7 -> - | AB14: 20 | AC14: 20 | AD14: =AC14/AB14 -> 1 | AE14: =[9]Summary!$V$7 -> - | AH14: 20 | AI14: 2 | AJ14: =AI14/AH14 -> 0.1 | AL14: =[9]Summary!$Z$7 -> - | AN14: =[9]Summary!$AA$7 -> 42138 | AO14: =[9]Summary!$AB$7 -> ? | AP14: =[9]Summary!$AC$7 -> ? | AQ14: =[9]Summary!$AD$7 -> ? | AR14: =[9]Summary!$AE$7 -> RTL: POST: FPGA:
B15: 10 | C15: =[10]Summary!$B$7 -> Back Bone | D15: =[10]Summary!$C$7 -> 최호윤 수석 | E15: =[10]Summary!$D$7 -> 최호윤 수석 | G15: 30 | H15: 10 | I15: 30 | J15: 25 | K15: =[10]Summary!$I$7 -> 0 | L15: =[10]Summary!$J$7 -> 0 | M15: =[10]Summary!$K$7 -> - | N15: =[10]Summary!$L$7 -> 0 | O15: =[10]Summary!$M$7 -> 0 | P15: =[10]Summary!$N$7 -> - | Q15: =G15+I15+K15 -> 60 | R15: =H15+J15+L15 -> 35 | S15: =R15/Q15 -> 0.58333333 | V15: 20 | W15: 20 | X15: =W15/V15 -> 1 | Z15: =[10]Summary!$R$7 -> - | AB15: 20 | AC15: 15 | AD15: =AC15/AB15 -> 0.75 | AE15: =[10]Summary!$V$7 -> - | AH15: 20 | AI15: 5 | AJ15: =AI15/AH15 -> 0.25 | AL15: =[10]Summary!$Z$7 -> - | AN15: =[10]Summary!$AA$7 -> 42138 | AO15: =[10]Summary!$AB$7 -> ? | AP15: =[10]Summary!$AC$7 -> ? | AQ15: =[10]Summary!$AD$7 -> ? | AR15: =[10]Summary!$AE$7 -> RTL: POST: FPGA:
B16: 11 | C16: =[11]Summary!$B$7 -> System Controller | D16: =[11]Summary!$C$7 -> 김정욱 책임 | E16: =[11]Summary!$D$7 -> 김정욱 책임 | G16: 20 | H16: 18 | I16: 30 | J16: 22 | K16: =[11]Summary!$I$7 -> 0 | L16: =[11]Summary!$J$7 -> 0 | M16: =[11]Summary!$K$7 -> - | N16: =[11]Summary!$L$7 -> 0 | O16: =[11]Summary!$M$7 -> 0 | P16: =[11]Summary!$N$7 -> - | Q16: =G16+I16+K16 -> 50 | R16: =H16+J16+L16 -> 40 | S16: =R16/Q16 -> 0.8 | V16: 30 | W16: 15 | X16: =W16/V16 -> 0.5 | Z16: =[11]Summary!$R$7 -> - | AB16: 35 | AC16: 30 | AD16: =AC16/AB16 -> 0.85714286 | AE16: =[11]Summary!$V$7 -> - | AH16: 15 | AI16: 2 | AJ16: =AI16/AH16 -> 0.13333333 | AL16: =[11]Summary!$Z$7 -> - | AN16: =[11]Summary!$AA$7 -> 42138 | AO16: =[11]Summary!$AB$7 -> ? | AP16: =[11]Summary!$AC$7 -> ? | AQ16: =[11]Summary!$AD$7 -> ? | AR16: =[11]Summary!$AE$7 -> RTL: POST: FPGA:
B17: 12 | C17: =[12]Summary!$B$7 -> PMU | D17: =[12]Summary!$C$7 -> 김정욱 책임 | E17: =[12]Summary!$D$7 -> 김정욱 책임 | G17: 15 | H17: 14 | I17: 30 | J17: 25 | K17: =[12]Summary!$I$7 -> 0 | L17: =[12]Summary!$J$7 -> 0 | M17: =[12]Summary!$K$7 -> - | N17: =[12]Summary!$L$7 -> 0 | O17: =[12]Summary!$M$7 -> 0 | P17: =[12]Summary!$N$7 -> - | Q17: =G17+I17+K17 -> 45 | R17: =H17+J17+L17 -> 39 | S17: =R17/Q17 -> 0.86666667 | V17: 30 | W17: 15 | X17: =W17/V17 -> 0.5 | Z17: =[12]Summary!$R$7 -> - | AB17: 30 | AC17: 25 | AD17: =AC17/AB17 -> 0.83333333 | AE17: =[12]Summary!$V$7 -> - | AH17: 20 | AI17: 5 | AJ17: =AI17/AH17 -> 0.25 | AL17: =[12]Summary!$Z$7 -> - | AN17: =[12]Summary!$AA$7 -> 42138 | AO17: =[12]Summary!$AB$7 -> ? | AP17: =[12]Summary!$AC$7 -> ? | AQ17: =[12]Summary!$AD$7 -> ? | AR17: =[12]Summary!$AE$7 -> RTL: POST: FPGA:
B18: 13 | C18: =[13]Summary!$B$7 -> RPMB | D18: =[13]Summary!$C$7 -> 안병욱 선임 | E18: =[13]Summary!$D$7 -> 안병욱 선임 | G18: 20 | H18: 18 | I18: 35 | J18: 23 | K18: =[13]Summary!$I$7 -> 0 | L18: =[13]Summary!$J$7 -> 0 | M18: =[13]Summary!$K$7 -> - | N18: =[13]Summary!$L$7 -> 0 | O18: =[13]Summary!$M$7 -> 0 | P18: =[13]Summary!$N$7 -> - | Q18: =G18+I18+K18 -> 55 | R18: =H18+J18+L18 -> 41 | S18: =R18/Q18 -> 0.74545455 | V18: 20 | W18: 20 | X18: =W18/V18 -> 1 | Z18: =[13]Summary!$R$7 -> - | AB18: 30 | AC18: 25 | AD18: =AC18/AB18 -> 0.83333333 | AE18: =[13]Summary!$V$7 -> - | AH18: 25 | AI18: 2 | AJ18: =AI18/AH18 -> 0.08 | AL18: =[13]Summary!$Z$7 -> - | AN18: =[13]Summary!$AA$7 -> 42138 | AO18: =[13]Summary!$AB$7 -> ? | AP18: =[13]Summary!$AC$7 -> ? | AQ18: =[13]Summary!$AD$7 -> ? | AR18: =[13]Summary!$AE$7 -> RTL: POST: FPGA:
B19: 14 | C19: =[14]Summary!$B$7 -> Mail Box | D19: =[14]Summary!$C$7 -> 안병욱 선임 | E19: =[14]Summary!$D$7 -> 안병욱 선임 | G19: 30 | H19: 20 | I19: 20 | J19: 18 | K19: =[14]Summary!$I$7 -> 0 | L19: =[14]Summary!$J$7 -> 0 | M19: =[14]Summary!$K$7 -> - | N19: =[14]Summary!$L$7 -> 0 | O19: =[14]Summary!$M$7 -> 0 | P19: =[14]Summary!$N$7 -> - | Q19: =G19+I19+K19 -> 50 | R19: =H19+J19+L19 -> 38 | S19: =R19/Q19 -> 0.76 | V19: 35 | W19: 30 | X19: =W19/V19 -> 0.85714286 | Z19: =[14]Summary!$R$7 -> - | AB19: 30 | AC19: 24 | AD19: =AC19/AB19 -> 0.8 | AE19: =[14]Summary!$V$7 -> - | AH19: 25 | AI19: 5 | AJ19: =AI19/AH19 -> 0.2 | AL19: =[14]Summary!$Z$7 -> - | AN19: =[14]Summary!$AA$7 -> 42138 | AO19: =[14]Summary!$AB$7 -> ? | AP19: =[14]Summary!$AC$7 -> ? | AQ19: =[14]Summary!$AD$7 -> ? | AR19: =[14]Summary!$AE$7 -> RTL: POST: FPGA:
B20: 15 | C20: =[15]Summary!$B$7 -> Timer | D20: =[15]Summary!$C$7 -> 안병욱 선임 | E20: =[15]Summary!$D$7 -> 안병욱 선임 | G20: 15 | H20: 10 | I20: 20 | J20: 15 | K20: =[15]Summary!$I$7 -> 0 | L20: =[15]Summary!$J$7 -> 0 | M20: =[15]Summary!$K$7 -> - | N20: =[15]Summary!$L$7 -> 0 | O20: =[15]Summary!$M$7 -> 0 | P20: =[15]Summary!$N$7 -> - | Q20: =G20+I20+K20 -> 35 | R20: =H20+J20+L20 -> 25 | S20: =R20/Q20 -> 0.71428571 | V20: 35 | W20: 30 | X20: =W20/V20 -> 0.85714286 | Z20: =[15]Summary!$R$7 -> - | AB20: 30 | AC20: 28 | AD20: =AC20/AB20 -> 0.93333333 | AE20: =[15]Summary!$V$7 -> - | AH20: 25 | AI20: 10 | AJ20: =AI20/AH20 -> 0.4 | AL20: =[15]Summary!$Z$7 -> - | AN20: =[15]Summary!$AA$7 -> 42138 | AO20: =[15]Summary!$AB$7 -> ? | AP20: =[15]Summary!$AC$7 -> ? | AQ20: =[15]Summary!$AD$7 -> ? | AR20: =[15]Summary!$AE$7 -> RTL: POST: FPGA:
B21: 16 | C21: =[16]Summary!$B$7 -> WDT | D21: =[16]Summary!$C$7 -> 안병욱 선임 | E21: =[16]Summary!$D$7 -> 안병욱 선임 | G21: 18 | H21: 10 | I21: 20 | J21: 16 | K21: =[16]Summary!$I$7 -> 0 | L21: =[16]Summary!$J$7 -> 0 | M21: =[16]Summary!$K$7 -> - | N21: =[16]Summary!$L$7 -> 0 | O21: =[16]Summary!$M$7 -> 0 | P21: =[16]Summary!$N$7 -> - | Q21: =G21+I21+K21 -> 38 | R21: =H21+J21+L21 -> 26 | S21: =R21/Q21 -> 0.68421053 | V21: 35 | W21: 30 | X21: =W21/V21 -> 0.85714286 | Z21: =[16]Summary!$R$7 -> - | AB21: 40 | AC21: 32 | AD21: =AC21/AB21 -> 0.8 | AE21: =[16]Summary!$V$7 -> - | AH21: 20 | AI21: 2 | AJ21: =AI21/AH21 -> 0.1 | AL21: =[16]Summary!$Z$7 -> - | AN21: =[16]Summary!$AA$7 -> 42138 | AO21: =[16]Summary!$AB$7 -> ? | AP21: =[16]Summary!$AC$7 -> ? | AQ21: =[16]Summary!$AD$7 -> ? | AR21: =[16]Summary!$AE$7 -> RTL: POST: FPGA:
B22: 17 | C22: =[17]Summary!$B$7 -> UART | D22: =[17]Summary!$C$7 -> 안병욱 선임 | E22: =[17]Summary!$D$7 -> 안병욱 선임 | G22: 17 | H22: 15 | I22: 25 | J22: 20 | K22: =[17]Summary!$I$7 -> 0 | L22: =[17]Summary!$J$7 -> 0 | M22: =[17]Summary!$K$7 -> - | N22: =[17]Summary!$L$7 -> 0 | O22: =[17]Summary!$M$7 -> 0 | P22: =[17]Summary!$N$7 -> - | Q22: =G22+I22+K22 -> 42 | R22: =H22+J22+L22 -> 35 | S22: =R22/Q22 -> 0.83333333 | V22: 25 | W22: 30 | X22: =W22/V22 -> 1.2 | Z22: =[17]Summary!$R$7 -> - | AB22: 25 | AC22: 20 | AD22: =AC22/AB22 -> 0.8 | AE22: =[17]Summary!$V$7 -> - | AH22: 30 | AI22: 2 | AJ22: =AI22/AH22 -> 0.066666667 | AL22: =[17]Summary!$Z$7 -> - | AN22: =[17]Summary!$AA$7 -> 42138 | AO22: =[17]Summary!$AB$7 -> ? | AP22: =[17]Summary!$AC$7 -> ? | AQ22: =[17]Summary!$AD$7 -> ? | AR22: =[17]Summary!$AE$7 -> RTL: POST: FPGA:
B23: 18 | C23: =[18]Summary!$B$7 -> Clock Controller | D23: =[18]Summary!$C$7 -> 김정욱 책임 | E23: =[18]Summary!$D$7 -> 김정욱 책임 | G23: 16 | H23: 15 | I23: 25 | J23: 25 | K23: =[18]Summary!$I$7 -> 0 | L23: =[18]Summary!$J$7 -> 0 | M23: =[18]Summary!$K$7 -> - | N23: =[18]Summary!$L$7 -> 0 | O23: =[18]Summary!$M$7 -> 0 | P23: =[18]Summary!$N$7 -> - | Q23: =G23+I23+K23 -> 41 | R23: =H23+J23+L23 -> 40 | S23: =R23/Q23 -> 0.97560976 | V23: 25 | W23: 20 | X23: =W23/V23 -> 0.8 | Z23: =[18]Summary!$R$7 -> - | AB23: 25 | AC23: 25 | AD23: =AC23/AB23 -> 1 | AE23: =[18]Summary!$V$7 -> - | AH23: 30 | AI23: 5 | AJ23: =AI23/AH23 -> 0.16666667 | AL23: =[18]Summary!$Z$7 -> - | AN23: =[18]Summary!$AA$7 -> 42138 | AO23: =[18]Summary!$AB$7 -> ? | AP23: =[18]Summary!$AC$7 -> ? | AQ23: =[18]Summary!$AD$7 -> ? | AR23: =[18]Summary!$AE$7 -> RTL: POST: FPGA:
B24: 19 | C24: =[19]Summary!$B$7 -> Reset Controller | D24: =[19]Summary!$C$7 -> 김정욱 책임 | E24: =[19]Summary!$D$7 -> 김정욱 책임 | G24: 20 | H24: 13 | I24: 25 | J24: 22 | K24: =[19]Summary!$I$7 -> 0 | L24: =[19]Summary!$J$7 -> 0 | M24: =[19]Summary!$K$7 -> - | N24: =[19]Summary!$L$7 -> 0 | O24: =[19]Summary!$M$7 -> 0 | P24: =[19]Summary!$N$7 -> - | Q24: =G24+I24+K24 -> 45 | R24: =H24+J24+L24 -> 35 | S24: =R24/Q24 -> 0.77777778 | V24: 25 | W24: 20 | X24: =W24/V24 -> 0.8 | Z24: =[19]Summary!$R$7 -> - | AB24: 25 | AC24: 22 | AD24: =AC24/AB24 -> 0.88 | AE24: =[19]Summary!$V$7 -> - | AH24: 30 | AI24: 8 | AJ24: =AI24/AH24 -> 0.26666667 | AL24: =[19]Summary!$Z$7 -> - | AN24: =[19]Summary!$AA$7 -> 42138 | AO24: =[19]Summary!$AB$7 -> ? | AP24: =[19]Summary!$AC$7 -> ? | AQ24: =[19]Summary!$AD$7 -> ? | AR24: =[19]Summary!$AE$7 -> RTL: POST: FPGA:
B25: 20 | C25: =[20]Summary!$B$7 -> eFuse Controller | D25: =[20]Summary!$C$7 -> 안병욱 선임 | E25: =[20]Summary!$D$7 -> 안병욱 선임 | G25: 21 | H25: 20 | I25: 25 | J25: 22 | K25: =[20]Summary!$I$7 -> 0 | L25: =[20]Summary!$J$7 -> 0 | M25: =[20]Summary!$K$7 -> - | N25: =[20]Summary!$L$7 -> 0 | O25: =[20]Summary!$M$7 -> 0 | P25: =[20]Summary!$N$7 -> - | Q25: =G25+I25+K25 -> 46 | R25: =H25+J25+L25 -> 42 | S25: =R25/Q25 -> 0.91304348 | V25: 40 | W25: 35 | X25: =W25/V25 -> 0.875 | Z25: =[20]Summary!$R$7 -> - | AB25: 25 | AC25: 22 | AD25: =AC25/AB25 -> 0.88 | AE25: =[20]Summary!$V$7 -> - | AH25: 25 | AI25: 9 | AJ25: =AI25/AH25 -> 0.36 | AL25: =[20]Summary!$Z$7 -> - | AN25: =[20]Summary!$AA$7 -> 42138 | AO25: =[20]Summary!$AB$7 -> ? | AP25: =[20]Summary!$AC$7 -> ? | AQ25: =[20]Summary!$AD$7 -> ? | AR25: =[20]Summary!$AE$7 -> RTL: POST: FPGA:
B26: 21 | C26: =[21]Summary!$B$7 -> M-PHY | D26: =[21]Summary!$C$7 -> 이현주 선임 | E26: =[21]Summary!$D$7 -> 이현주 선임 | G26: 25 | H26: 22 | I26: 25 | J26: 23 | K26: =[21]Summary!$I$7 -> 0 | L26: =[21]Summary!$J$7 -> 0 | M26: =[21]Summary!$K$7 -> - | N26: =[21]Summary!$L$7 -> 0 | O26: =[21]Summary!$M$7 -> 0 | P26: =[21]Summary!$N$7 -> - | Q26: =G26+I26+K26 -> 50 | R26: =H26+J26+L26 -> 45 | S26: =R26/Q26 -> 0.9 | V26: 40 | W26: 30 | X26: =W26/V26 -> 0.75 | Z26: =[21]Summary!$R$7 -> - | AB26: 25 | AC26: 23 | AD26: =AC26/AB26 -> 0.92 | AE26: =[21]Summary!$V$7 -> - | AH26: 25 | AI26: 7 | AJ26: =AI26/AH26 -> 0.28 | AL26: =[21]Summary!$Z$7 -> - | AN26: =[21]Summary!$AA$7 -> 42138 | AO26: =[21]Summary!$AB$7 -> ? | AP26: =[21]Summary!$AC$7 -> ? | AQ26: =[21]Summary!$AD$7 -> ? | AR26: =[21]Summary!$AE$7 -> RTL: POST: FPGA:
B27: 22 | C27: =[22]Summary!$B$7 -> Nand PHY | D27: =[22]Summary!$C$7 -> 이종용 선임 | E27: =[22]Summary!$D$7 -> 이종용 선임 | G27: 20 | H27: 20 | I27: 30 | J27: 25 | K27: =[22]Summary!$I$7 -> 0 | L27: =[22]Summary!$J$7 -> 0 | M27: =[22]Summary!$K$7 -> - | N27: =[22]Summary!$L$7 -> 0 | O27: =[22]Summary!$M$7 -> 0 | P27: =[22]Summary!$N$7 -> - | Q27: =G27+I27+K27 -> 50 | R27: =H27+J27+L27 -> 45 | S27: =R27/Q27 -> 0.9 | V27: 35 | W27: 30 | X27: =W27/V27 -> 0.85714286 | Z27: =[22]Summary!$R$7 -> - | AB27: 30 | AC27: 30 | AD27: =AC27/AB27 -> 1 | AE27: =[22]Summary!$V$7 -> - | AH27: 30 | AI27: 5 | AJ27: =AI27/AH27 -> 0.16666667 | AL27: =[22]Summary!$Z$7 -> - | AN27: =[22]Summary!$AA$7 -> 42138 | AO27: =[22]Summary!$AB$7 -> ? | AP27: =[22]Summary!$AC$7 -> ? | AQ27: =[22]Summary!$AD$7 -> ? | AR27: =[22]Summary!$AE$7 -> RTL: POST: FPGA:
B28: 23 | C28: =[23]Summary!$B$7 -> Nand IO | D28: =[23]Summary!$C$7 -> 이종용 선임 | E28: =[23]Summary!$D$7 -> 이종용 선임 | G28: 30 | H28: 25 | I28: 35 | J28: 30 | K28: =[23]Summary!$I$7 -> 0 | L28: =[23]Summary!$J$7 -> 0 | M28: =[23]Summary!$K$7 -> - | N28: =[23]Summary!$L$7 -> 0 | O28: =[23]Summary!$M$7 -> 0 | P28: =[23]Summary!$N$7 -> - | Q28: =G28+I28+K28 -> 65 | R28: =H28+J28+L28 -> 55 | S28: =R28/Q28 -> 0.84615385 | V28: 35 | W28: 30 | X28: =W28/V28 -> 0.85714286 | Z28: =[23]Summary!$R$7 -> - | AB28: 20 | AC28: 18 | AD28: =AC28/AB28 -> 0.9 | AE28: =[23]Summary!$V$7 -> - | AH28: 30 | AI28: 8 | AJ28: =AI28/AH28 -> 0.26666667 | AL28: =[23]Summary!$Z$7 -> - | AN28: =[23]Summary!$AA$7 -> 42138 | AO28: =[23]Summary!$AB$7 -> ? | AP28: =[23]Summary!$AC$7 -> ? | AQ28: =[23]Summary!$AD$7 -> ? | AR28: =[23]Summary!$AE$7 -> RTL: POST: FPGA:
B29: 24 | C29: =[24]Summary!$B$7 -> Test Mux | D29: =[24]Summary!$C$7 -> 양창호 선임 | E29: =[24]Summary!$D$7 -> 양창호 선임 | G29: 35 | H29: 30 | I29: 20 | J29: 15 | K29: =[24]Summary!$I$7 -> 0 | L29: =[24]Summary!$J$7 -> 0 | M29: =[24]Summary!$K$7 -> - | N29: =[24]Summary!$L$7 -> 0 | O29: =[24]Summary!$M$7 -> 0 | P29: =[24]Summary!$N$7 -> - | Q29: =G29+I29+K29 -> 55 | R29: =H29+J29+L29 -> 45 | S29: =R29/Q29 -> 0.81818182 | V29: 20 | W29: 20 | X29: =W29/V29 -> 1 | Z29: =[24]Summary!$R$7 -> - | AB29: 30 | AC29: 15 | AD29: =AC29/AB29 -> 0.5 | AE29: =[24]Summary!$V$7 -> - | AH29: 25 | AI29: 2 | AJ29: =AI29/AH29 -> 0.08 | AL29: =[24]Summary!$Z$7 -> - | AN29: =[24]Summary!$AA$7 -> 42138 | AO29: =[24]Summary!$AB$7 -> ? | AP29: =[24]Summary!$AC$7 -> ? | AQ29: =[24]Summary!$AD$7 -> ? | AR29: =[24]Summary!$AE$7 -> RTL: POST: FPGA:
B30: 25 | C30: =[25]Summary!$B$7 -> HW Bypass | D30: =[25]Summary!$C$7 -> 양창호 선임 | E30: =[25]Summary!$D$7 -> 양창호 선임 | G30: 20 | H30: 20 | I30: 25 | J30: 25 | K30: =[25]Summary!$I$7 -> 0 | L30: =[25]Summary!$J$7 -> 0 | M30: =[25]Summary!$K$7 -> - | N30: =[25]Summary!$L$7 -> 0 | O30: =[25]Summary!$M$7 -> 0 | P30: =[25]Summary!$N$7 -> - | Q30: =G30+I30+K30 -> 45 | R30: =H30+J30+L30 -> 45 | S30: =R30/Q30 -> 1 | V30: 25 | W30: 20 | X30: =W30/V30 -> 0.8 | Z30: =[25]Summary!$R$7 -> - | AB30: 25 | AC30: 5 | AD30: =AC30/AB30 -> 0.2 | AE30: =[25]Summary!$V$7 -> - | AH30: 30 | AI30: 2 | AJ30: =AI30/AH30 -> 0.066666667 | AL30: =[25]Summary!$Z$7 -> - | AN30: =[25]Summary!$AA$7 -> 42138 | AO30: =[25]Summary!$AB$7 -> ? | AP30: =[25]Summary!$AC$7 -> ? | AQ30: =[25]Summary!$AD$7 -> ? | AR30: =[25]Summary!$AE$7 -> RTL: POST: FPGA:
B31: 26 | C31: =[26]Summary!$B$7 -> Analog IP | D31: =[26]Summary!$C$7 -> 양창호 선임 | E31: =[26]Summary!$D$7 -> 양창호 선임 | G31: 20 | H31: 18 | I31: 30 | J31: 30 | K31: =[26]Summary!$I$7 -> 0 | L31: =[26]Summary!$J$7 -> 0 | M31: =[26]Summary!$K$7 -> - | N31: =[26]Summary!$L$7 -> 0 | O31: =[26]Summary!$M$7 -> 0 | P31: =[26]Summary!$N$7 -> - | Q31: =G31+I31+K31 -> 50 | R31: =H31+J31+L31 -> 48 | S31: =R31/Q31 -> 0.96 | V31: 30 | W31: 20 | X31: =W31/V31 -> 0.66666667 | Z31: =[26]Summary!$R$7 -> - | AB31: 30 | AC31: 2 | AD31: =AC31/AB31 -> 0.066666667 | AE31: =[26]Summary!$V$7 -> - | AH31: 40 | AI31: 5 | AJ31: =AI31/AH31 -> 0.125 | AL31: =[26]Summary!$Z$7 -> - | AN31: =[26]Summary!$AA$7 -> 42138 | AO31: =[26]Summary!$AB$7 -> ? | AP31: =[26]Summary!$AC$7 -> ? | AQ31: =[26]Summary!$AD$7 -> ? | AR31: =[26]Summary!$AE$7 -> RTL: POST: FPGA:
B32: 27 | C32: =[27]Summary!$B$7 -> GPIO | D32: =[27]Summary!$C$7 -> 양창호 선임 | E32: =[27]Summary!$D$7 -> 양창호 선임 | G32: 20 | H32: 10 | I32: 40 | J32: 35 | K32: =[27]Summary!$I$7 -> 0 | L32: =[27]Summary!$J$7 -> 0 | M32: =[27]Summary!$K$7 -> - | N32: =[27]Summary!$L$7 -> 0 | O32: =[27]Summary!$M$7 -> 0 | P32: =[27]Summary!$N$7 -> - | Q32: =G32+I32+K32 -> 60 | R32: =H32+J32+L32 -> 45 | S32: =R32/Q32 -> 0.75 | V32: 30 | W32: 20 | X32: =W32/V32 -> 0.66666667 | Z32: =[27]Summary!$R$7 -> - | AB32: 20 | AC32: 3 | AD32: =AC32/AB32 -> 0.15 | AE32: =[27]Summary!$V$7 -> - | AH32: 50 | AI32: 2 | AJ32: =AI32/AH32 -> 0.04 | AL32: =[27]Summary!$Z$7 -> - | AN32: =[27]Summary!$AA$7 -> 42138 | AO32: =[27]Summary!$AB$7 -> ? | AP32: =[27]Summary!$AC$7 -> ? | AQ32: =[27]Summary!$AD$7 -> ? | AR32: =[27]Summary!$AE$7 -> RTL: POST: FPGA:
B33: - | C33: =[28]Summary!$B$7 -> End to End | D33: =[28]Summary!$C$7 -> ALL | E33: =[28]Summary!$D$7 -> 조성엽 책임 | G33: 10 | H33: 5 | I33: 10 | J33: =[28]Summary!$H$7 -> 0 | K33: =[28]Summary!$I$7 -> 0 | L33: =[28]Summary!$J$7 -> 0 | M33: =[28]Summary!$K$7 -> - | N33: =[28]Summary!$L$7 -> 0 | O33: =[28]Summary!$M$7 -> 0 | P33: =[28]Summary!$N$7 -> - | Q33: =G33+I33+K33 -> 20 | R33: =H33+J33+L33 -> 5 | S33: =R33/Q33 -> 0.25 | V33: 25 | W33: 15 | X33: =W33/V33 -> 0.6 | Z33: =[28]Summary!$R$7 -> - | AB33: 25 | AC33: 5 | AD33: =AC33/AB33 -> 0.2 | AE33: =[28]Summary!$V$7 -> - | AH33: 20 | AI33: 5 | AJ33: =AI33/AH33 -> 0.25 | AL33: =[28]Summary!$Z$7 -> - | AN33: =[28]Summary!$AA$7 -> 42138 | AO33: =[28]Summary!$AB$7 -> ? | AP33: =[28]Summary!$AC$7 -> ? | AQ33: =[28]Summary!$AD$7 -> ? | AR33: =[28]Summary!$AE$7 -> RTL: POST: FPGA:
B34: - | C34: =[29]Summary!$B$7 -> Post-Silicon Validation | D34: =[29]Summary!$C$7 -> ALL | E34: =[29]Summary!$D$7 -> ALL
B35: Sub Average | G35: =AVERAGE(G6:G33) -> 18.714286 | H35: =AVERAGE(H6:H33) -> 14.642857 | I35: =AVERAGE(I6:I33) -> 24 | J35: =AVERAGE(J6:J33) -> 19.035714 | K35: =AVERAGE(K6:K33) -> 0 | L35: =AVERAGE(L6:L33) -> 0 | N35: =AVERAGE(N7:N33) -> 0 | O35: =AVERAGE(O6:O33) -> 0 | Q35: =AVERAGE(Q6:Q33) -> 42.714286 | R35: =AVERAGE(R6:R33) -> 33.678571 | V35: =AVERAGE(V6:V33) -> 30.357143 | W35: =AVERAGE(W6:W33) -> 24.678571 | X35: - | AB35: =AVERAGE(AB6:AB33) -> 26.428571 | AC35: =AVERAGE(AC6:AC33) -> 19.357143 | AD35: - | AH35: =AVERAGE(AH6:AH33) -> 26.607143 | AI35: =AVERAGE(AI6:AI33) -> 4.2142857 | AJ35: -
B36: Sub Sum | G36: =SUM(G6:G33) -> 524 | H36: =SUM(H6:H33) -> 410 | I36: =SUM(I6:I33) -> 672 | J36: =SUM(J6:J33) -> 533 | K36: =SUM(K6:K33) -> 0 | L36: =SUM(L6:L33) -> 0 | M36: =IF(G36=0, "-", L36/G36) -> 0 | N36: - | O36: - | Q36: =SUM(Q6:Q33) -> 1196 | R36: =SUM(R6:R33) -> 943 | V36: =SUM(V6:V33) -> 850 | W36: =SUM(W6:W33) -> 691 | X36: =IF(V36=0, "-", W36/V36) -> 0.81294118 | AB36: =SUM(AB6:AB33) -> 740 | AC36: =SUM(AC6:AC33) -> 542 | AD36: =IF(AB36=0, "-", AC36/AB36) -> 0.73243243 | AH36: =SUM(AH6:AH33) -> 745 | AI36: =SUM(AI6:AI33) -> 118 | AJ36: =IF(AH36=0, "-", AI36/AH36) -> 0.15838926
B37: Total | V37: =G36+V36 -> 1374 | W37: =L36+W36 -> 691 | X37: =IF(V37=0, "-", W37/V37) -> 0.50291121
AN39: 1
AN40: 0.9
AN41: 0.7
AN42: 0.5
...

Sheet Chart 1 - data
B2: Columbus Verification Status Summary | AK2: 42138
B3: No. | C3: IP | D3: RTL Designer | E3: Verification Engineer | G3: RTL Sim. | T3: FPGA | Y3: POST Sim. | AD3: ASIC | AI3: Last Updated | AM3: Remark / Coverage Waive
G4: F1 | I4: F2 | K4: F3 | M4: F1~3 | N4: Cov. SoC (F2,F3) | O4: Cov. S.A (F0,F1) | P4: Done | T4: Cases | U4: Pass | V4: Prog. | W4: Done | Y4: Cases | Z4: Pass | AA4: Prog. | AB4: Done | AD4: Cases | AE4: Pass | AF4: Prog. | AG4: Done | AI4: Date | AJ4: RTL | AK4: FPGA | AL4: ASIC
C5: IP | G5: Cases | H5: Pass | I5: Cases | J5: Pass | K5: Cases | L5: Pass | M5: Prog. | Q5: RTL Case | R5: RTL Pass | T5: FPGA Case | U5: FPGA Pass | Y5: Sim. Case | Z5: Sim. Pass | AD5: ASIC Case | AE5: ASIC Pass
B6: 1 | C6: =[1]Summary!$B$7 -> Cortex-M3 | D6: =[1]Summary!$C$7 -> 최호윤 수석 | E6: =[1]Summary!$D$7 -> 조성엽 책임 | G6: 10 | H6: 10 | I6: 12 | J6: 5 | K6: =[1]Summary!$I$7 -> 0 | L6: =[1]Summary!$J$7 -> 0 | M6: =[1]Summary!$K$7 -> - | N6: =[1]Summary!$L$7 -> 0 | O6: =[1]Summary!$M$7 -> 0 | P6: =[1]Summary!$N$7 -> - | Q6: =G6+I6+K6 -> 22 | R6: =H6+J6+L6 -> 15 | T6: 30 | U6: 26 | V6: =[1]Summary!$Q$7 -> - | W6: =[1]Summary!$R$7 -> - | Y6: 20 | Z6: 10 | AA6: =[1]Summary!$U$7 -> - | AB6: =[1]Summary!$V$7 -> - | AD6: 20 | AE6: 5 | AF6: =[1]Summary!$Y$7 -> - | AG6: =[1]Summary!$Z$7 -> - | AI6: =[1]Summary!$AA$7 -> 42138 | AJ6: =[1]Summary!$AB$7 -> ? | AK6: =[1]Summary!$AC$7 -> ? | AL6: =[1]Summary!$AD$7 -> ? | AM6: =[1]Summary!$AE$7 -> RTL: POST: FPGA:
B7: 2 | C7: =[2]Summary!$B$7 -> HCT | D7: =[2]Summary!$C$7 -> 이원규 선임 | E7: =[2]Summary!$D$7 -> 박재우 책임 | G7: 15 | H7: 5 | I7: 12 | J7: 5 | K7: =[2]Summary!$I$7 -> 0 | L7: =[2]Summary!$J$7 -> 0 | M7: =[2]Summary!$K$7 -> - | N7: =[2]Summary!$L$7 -> 0 | O7: =[2]Summary!$M$7 -> 0 | P7: =[2]Summary!$N$7 -> - | Q7: =G7+I7+K7 -> 27 | R7: =H7+J7+L7 -> 10 | T7: 40 | U7: 25 | V7: =[2]Summary!$Q$7 -> - | W7: =[2]Summary!$R$7 -> - | Y7: 30 | Z7: 20 | AA7: =[2]Summary!$U$7 -> - | AB7: =[2]Summary!$V$7 -> - | AD7: 30 | AE7: 2 | AF7: =[2]Summary!$Y$7 -> - | AG7: =[2]Summary!$Z$7 -> - | AI7: =[2]Summary!$AA$7 -> 42138 | AJ7: =[2]Summary!$AB$7 -> ? | AK7: =[2]Summary!$AC$7 -> ? | AL7: =[2]Summary!$AD$7 -> ? | AM7: =[2]Summary!$AE$7 -> RTL: POST: FPGA:
B8: 3 | C8: =[3]Summary!$B$7 -> FCT | D8: =[3]Summary!$C$7 -> 천동엽 책임 | E8: =[3]Summary!$D$7 -> 조성엽 책임 | G8: 20 | H8: 18 | I8: 20 | J8: 15 | K8: =[3]Summary!$I$7 -> 0 | L8: =[3]Summary!$J$7 -> 0 | M8: =[3]Summary!$K$7 -> - | N8: =[3]Summary!$L$7 -> 0 | O8: =[3]Summary!$M$7 -> 0 | P8: =[3]Summary!$N$7 -> - | Q8: =G8+I8+K8 -> 40 | R8: =H8+J8+L8 -> 33 | T8: 30 | U8: 30 | V8: =[3]Summary!$Q$7 -> - | W8: =[3]Summary!$R$7 -> - | Y8: 30 | Z8: 25 | AA8: =[3]Summary!$U$7 -> - | AB8: =[3]Summary!$V$7 -> - | AD8: 30 | AE8: 3 | AF8: =[3]Summary!$Y$7 -> - | AG8: =[3]Summary!$Z$7 -> - | AI8: =[3]Summary!$AA$7 -> 42138 | AJ8: =[3]Summary!$AB$7 -> ? | AK8: =[3]Summary!$AC$7 -> ? | AL8: =[3]Summary!$AD$7 -> ? | AM8: =[3]Summary!$AE$7 -> RTL: POST: FPGA:
B9: 4 | C9: =[4]Summary!$B$7 -> Buffer Manager | D9: =[4]Summary!$C$7 -> 지대근 책임 | E9: =[4]Summary!$D$7 -> 조성엽 책임 | G9: 15 | H9: 10 | I9: 30 | J9: 20 | K9: =[4]Summary!$I$7 -> 0 | L9: =[4]Summary!$J$7 -> 0 | M9: =[4]Summary!$K$7 -> - | N9: =[4]Summary!$L$7 -> 0 | O9: =[4]Summary!$M$7 -> 0 | P9: =[4]Summary!$N$7 -> - | Q9: =G9+I9+K9 -> 45 | R9: =H9+J9+L9 -> 30 | T9: 20 | U9: 20 | V9: =[4]Summary!$Q$7 -> - | W9: =[4]Summary!$R$7 -> - | Y9: 40 | Z9: 30 | AA9: =[4]Summary!$U$7 -> - | AB9: =[4]Summary!$V$7 -> - | AD9: 30 | AE9: 2 | AF9: =[4]Summary!$Y$7 -> - | AG9: =[4]Summary!$Z$7 -> - | AI9: =[4]Summary!$AA$7 -> 42138 | AJ9: =[4]Summary!$AB$7 -> ? | AK9: =[4]Summary!$AC$7 -> ? | AL9: =[4]Summary!$AD$7 -> ? | AM9: =[4]Summary!$AE$7 -> RTL: POST: FPGA:
B10: 5 | C10: =[5]Summary!$B$7 -> Search Engine | D10: =[5]Summary!$C$7 -> 김현욱 선임 | E10: =[5]Summary!$D$7 -> 김현욱 선임 | G10: 20 | H10: 16 | I10: 15 | J10: 10 | K10: =[5]Summary!$I$7 -> 0 | L10: =[5]Summary!$J$7 -> 0 | M10: =[5]Summary!$K$7 -> - | N10: =[5]Summary!$L$7 -> 0 | O10: =[5]Summary!$M$7 -> 0 | P10: =[5]Summary!$N$7 -> - | Q10: =G10+I10+K10 -> 35 | R10: =H10+J10+L10 -> 26 | T10: 20 | U10: 20 | V10: =[5]Summary!$Q$7 -> - | W10: =[5]Summary!$R$7 -> - | Y10: 20 | Z10: 15 | AA10: =[5]Summary!$U$7 -> - | AB10: =[5]Summary!$V$7 -> - | AD10: 30 | AE10: 2 | AF10: =[5]Summary!$Y$7 -> - | AG10: =[5]Summary!$Z$7 -> - | AI10: =[5]Summary!$AA$7 -> 42138 | AJ10: =[5]Summary!$AB$7 -> ? | AK10: =[5]Summary!$AC$7 -> ? | AL10: =[5]Summary!$AD$7 -> ? | AM10: =[5]Summary!$AE$7 -> RTL: POST: FPGA:
B11: 6 | C11: =[6]Summary!$B$7 -> MTSE | D11: =[6]Summary!$C$7 -> 김현욱 선임 | E11: =[6]Summary!$D$7 -> 김현욱 선임 | G11: 15 | H11: 14 | I11: 20 | J11: 15 | K11: =[6]Summary!$I$7 -> 0 | L11: =[6]Summary!$J$7 -> 0 | M11: =[6]Summary!$K$7 -> - | N11: =[6]Summary!$L$7 -> 0 | O11: =[6]Summary!$M$7 -> 0 | P11: =[6]Summary!$N$7 -> - | Q11: =G11+I11+K11 -> 35 | R11: =H11+J11+L11 -> 29 | T11: 30 | U11: 25 | V11: =[6]Summary!$Q$7 -> - | W11: =[6]Summary!$R$7 -> - | Y11: 20 | Z11: 15 | AA11: =[6]Summary!$U$7 -> - | AB11: =[6]Summary!$V$7 -> - | AD11: 30 | AE11: 4 | AF11: =[6]Summary!$Y$7 -> - | AG11: =[6]Summary!$Z$7 -> - | AI11: =[6]Summary!$AA$7 -> 42138 | AJ11: =[6]Summary!$AB$7 -> ? | AK11: =[6]Summary!$AC$7 -> ? | AL11: =[6]Summary!$AD$7 -> ? | AM11: =[6]Summary!$AE$7 -> RTL: POST: FPGA:
B12: 7 | C12: =[7]Summary!$B$7 -> System Memory | D12: =[7]Summary!$C$7 -> 김현욱 선임 | E12: =[7]Summary!$D$7 -> 김현욱 선임 | G12: 10 | H12: 8 | I12: 15 | J12: 12 | K12: =[7]Summary!$I$7 -> 0 | L12: =[7]Summary!$J$7 -> 0 | M12: =[7]Summary!$K$7 -> - | N12: =[7]Summary!$L$7 -> 0 | O12: =[7]Summary!$M$7 -> 0 | P12: =[7]Summary!$N$7 -> - | Q12: =G12+I12+K12 -> 25 | R12: =H12+J12+L12 -> 20 | T12: 30 | U12: 20 | V12: =[7]Summary!$Q$7 -> - | W12: =[7]Summary!$R$7 -> - | Y12: 20 | Z12: 20 | AA12: =[7]Summary!$U$7 -> - | AB12: =[7]Summary!$V$7 -> - | AD12: 20 | AE12: 3 | AF12: =[7]Summary!$Y$7 -> - | AG12: =[7]Summary!$Z$7 -> - | AI12: =[7]Summary!$AA$7 -> 42138 | AJ12: =[7]Summary!$AB$7 -> ? | AK12: =[7]Summary!$AC$7 -> ? | AL12: =[7]Summary!$AD$7 -> ? | AM12: =[7]Summary!$AE$7 -> RTL: POST: FPGA:
B13: 8 | C13: =[8]Summary!$B$7 -> Data Buffer | D13: =[8]Summary!$C$7 -> 김현욱 선임 | E13: =[8]Summary!$D$7 -> 김현욱 선임 | G13: 8 | H13: 8 | I13: 18 | J13: 15 | K13: =[8]Summary!$I$7 -> 0 | L13: =[8]Summary!$J$7 -> 0 | M13: =[8]Summary!$K$7 -> - | N13: =[8]Summary!$L$7 -> 0 | O13: =[8]Summary!$M$7 -> 0 | P13: =[8]Summary!$N$7 -> - | Q13: =G13+I13+K13 -> 26 | R13: =H13+J13+L13 -> 23 | T13: 40 | U13: 35 | V13: =[8]Summary!$Q$7 -> - | W13: =[8]Summary!$R$7 -> - | Y13: 20 | Z13: 18 | AA13: =[8]Summary!$U$7 -> - | AB13: =[8]Summary!$V$7 -> - | AD13: 20 | AE13: 4 | AF13: =[8]Summary!$Y$7 -> - | AG13: =[8]Summary!$Z$7 -> - | AI13: =[8]Summary!$AA$7 -> 42138 | AJ13: =[8]Summary!$AB$7 -> ? | AK13: =[8]Summary!$AC$7 -> ? | AL13: =[8]Summary!$AD$7 -> ? | AM13: =[8]Summary!$AE$7 -> RTL: POST: FPGA:
B14: 9 | C14: =[9]Summary!$B$7 -> DMA | D14: =[9]Summary!$C$7 -> 김현욱 선임 | E14: =[9]Summary!$D$7 -> 김현욱 선임 | G14: 9 | H14: 8 | I14: 30 | J14: 20 | K14: =[9]Summary!$I$7 -> 0 | L14: =[9]Summary!$J$7 -> 0 | M14: =[9]Summary!$K$7 -> - | N14: =[9]Summary!$L$7 -> 0 | O14: =[9]Summary!$M$7 -> 0 | P14: =[9]Summary!$N$7 -> - | Q14: =G14+I14+K14 -> 39 | R14: =H14+J14+L14 -> 28 | T14: 50 | U14: 40 | V14: =[9]Summary!$Q$7 -> - | W14: =[9]Summary!$R$7 -> - | Y14: 20 | Z14: 20 | AA14: =[9]Summary!$U$7 -> - | AB14: =[9]Summary!$V$7 -> - | AD14: 20 | AE14: 2 | AF14: =[9]Summary!$Y$7 -> - | AG14: =[9]Summary!$Z$7 -> - | AI14: =[9]Summary!$AA$7 -> 42138 | AJ14: =[9]Summary!$AB$7 -> ? | AK14: =[9]Summary!$AC$7 -> ? | AL14: =[9]Summary!$AD$7 -> ? | AM14: =[9]Summary!$AE$7 -> RTL: POST: FPGA:
B15: 10 | C15: =[10]Summary!$B$7 -> Back Bone | D15: =[10]Summary!$C$7 -> 최호윤 수석 | E15: =[10]Summary!$D$7 -> 최호윤 수석 | G15: 30 | H15: 10 | I15: 30 | J15: 25 | K15: =[10]Summary!$I$7 -> 0 | L15: =[10]Summary!$J$7 -> 0 | M15: =[10]Summary!$K$7 -> - | N15: =[10]Summary!$L$7 -> 0 | O15: =[10]Summary!$M$7 -> 0 | P15: =[10]Summary!$N$7 -> - | Q15: =G15+I15+K15 -> 60 | R15: =H15+J15+L15 -> 35 | T15: 20 | U15: 20 | V15: =[10]Summary!$Q$7 -> - | W15: =[10]Summary!$R$7 -> - | Y15: 20 | Z15: 15 | AA15: =[10]Summary!$U$7 -> - | AB15: =[10]Summary!$V$7 -> - | AD15: 20 | AE15: 5 | AF15: =[10]Summary!$Y$7 -> - | AG15: =[10]Summary!$Z$7 -> - | AI15: =[10]Summary!$AA$7 -> 42138 | AJ15: =[10]Summary!$AB$7 -> ? | AK15: =[10]Summary!$AC$7 -> ? | AL15: =[10]Summary!$AD$7 -> ? | AM15: =[10]Summary!$AE$7 -> RTL: POST: FPGA:
B16: 11 | C16: =[11]Summary!$B$7 -> System Controller | D16: =[11]Summary!$C$7 -> 김정욱 책임 | E16: =[11]Summary!$D$7 -> 김정욱 책임 | G16: 20 | H16: 18 | I16: 30 | J16: 22 | K16: =[11]Summary!$I$7 -> 0 | L16: =[11]Summary!$J$7 -> 0 | M16: =[11]Summary!$K$7 -> - | N16: =[11]Summary!$L$7 -> 0 | O16: =[11]Summary!$M$7 -> 0 | P16: =[11]Summary!$N$7 -> - | Q16: =G16+I16+K16 -> 50 | R16: =H16+J16+L16 -> 40 | T16: 30 | U16: 15 | V16: =[11]Summary!$Q$7 -> - | W16: =[11]Summary!$R$7 -> - | Y16: 35 | Z16: 30 | AA16: =[11]Summary!$U$7 -> - | AB16: =[11]Summary!$V$7 -> - | AD16: 15 | AE16: 2 | AF16: =[11]Summary!$Y$7 -> - | AG16: =[11]Summary!$Z$7 -> - | AI16: =[11]Summary!$AA$7 -> 42138 | AJ16: =[11]Summary!$AB$7 -> ? | AK16: =[11]Summary!$AC$7 -> ? | AL16: =[11]Summary!$AD$7 -> ? | AM16: =[11]Summary!$AE$7 -> RTL: POST: FPGA:
B17: 12 | C17: =[12]Summary!$B$7 -> PMU | D17: =[12]Summary!$C$7 -> 김정욱 책임 | E17: =[12]Summary!$D$7 -> 김정욱 책임 | G17: 15 | H17: 14 | I17: 30 | J17: 25 | K17: =[12]Summary!$I$7 -> 0 | L17: =[12]Summary!$J$7 -> 0 | M17: =[12]Summary!$K$7 -> - | N17: =[12]Summary!$L$7 -> 0 | O17: =[12]Summary!$M$7 -> 0 | P17: =[12]Summary!$N$7 -> - | Q17: =G17+I17+K17 -> 45 | R17: =H17+J17+L17 -> 39 | T17: 30 | U17: 15 | V17: =[12]Summary!$Q$7 -> - | W17: =[12]Summary!$R$7 -> - | Y17: 30 | Z17: 25 | AA17: =[12]Summary!$U$7 -> - | AB17: =[12]Summary!$V$7 -> - | AD17: 20 | AE17: 5 | AF17: =[12]Summary!$Y$7 -> - | AG17: =[12]Summary!$Z$7 -> - | AI17: =[12]Summary!$AA$7 -> 42138 | AJ17: =[12]Summary!$AB$7 -> ? | AK17: =[12]Summary!$AC$7 -> ? | AL17: =[12]Summary!$AD$7 -> ? | AM17: =[12]Summary!$AE$7 -> RTL: POST: FPGA:
B18: 13 | C18: =[13]Summary!$B$7 -> RPMB | D18: =[13]Summary!$C$7 -> 안병욱 선임 | E18: =[13]Summary!$D$7 -> 안병욱 선임 | G18: 20 | H18: 18 | I18: 35 | J18: 23 | K18: =[13]Summary!$I$7 -> 0 | L18: =[13]Summary!$J$7 -> 0 | M18: =[13]Summary!$K$7 -> - | N18: =[13]Summary!$L$7 -> 0 | O18: =[13]Summary!$M$7 -> 0 | P18: =[13]Summary!$N$7 -> - | Q18: =G18+I18+K18 -> 55 | R18: =H18+J18+L18 -> 41 | T18: 20 | U18: 20 | V18: =[13]Summary!$Q$7 -> - | W18: =[13]Summary!$R$7 -> - | Y18: 30 | Z18: 25 | AA18: =[13]Summary!$U$7 -> - | AB18: =[13]Summary!$V$7 -> - | AD18: 25 | AE18: 2 | AF18: =[13]Summary!$Y$7 -> - | AG18: =[13]Summary!$Z$7 -> - | AI18: =[13]Summary!$AA$7 -> 42138 | AJ18: =[13]Summary!$AB$7 -> ? | AK18: =[13]Summary!$AC$7 -> ? | AL18: =[13]Summary!$AD$7 -> ? | AM18: =[13]Summary!$AE$7 -> RTL: POST: FPGA:
B19: 14 | C19: =[14]Summary!$B$7 -> Mail Box | D19: =[14]Summary!$C$7 -> 안병욱 선임 | E19: =[14]Summary!$D$7 -> 안병욱 선임 | G19: 30 | H19: 20 | I19: 20 | J19: 18 | K19: =[14]Summary!$I$7 -> 0 | L19: =[14]Summary!$J$7 -> 0 | M19: =[14]Summary!$K$7 -> - | N19: =[14]Summary!$L$7 -> 0 | O19: =[14]Summary!$M$7 -> 0 | P19: =[14]Summary!$N$7 -> - | Q19: =G19+I19+K19 -> 50 | R19: =H19+J19+L19 -> 38 | T19: 35 | U19: 30 | V19: =[14]Summary!$Q$7 -> - | W19: =[14]Summary!$R$7 -> - | Y19: 30 | Z19: 24 | AA19: =[14]Summary!$U$7 -> - | AB19: =[14]Summary!$V$7 -> - | AD19: 25 | AE19: 5 | AF19: =[14]Summary!$Y$7 -> - | AG19: =[14]Summary!$Z$7 -> - | AI19: =[14]Summary!$AA$7 -> 42138 | AJ19: =[14]Summary!$AB$7 -> ? | AK19: =[14]Summary!$AC$7 -> ? | AL19: =[14]Summary!$AD$7 -> ? | AM19: =[14]Summary!$AE$7 -> RTL: POST: FPGA:
B20: 15 | C20: =[15]Summary!$B$7 -> Timer | D20: =[15]Summary!$C$7 -> 안병욱 선임 | E20: =[15]Summary!$D$7 -> 안병욱 선임 | G20: 15 | H20: 10 | I20: 20 | J20: 15 | K20: =[15]Summary!$I$7 -> 0 | L20: =[15]Summary!$J$7 -> 0 | M20: =[15]Summary!$K$7 -> - | N20: =[15]Summary!$L$7 -> 0 | O20: =[15]Summary!$M$7 -> 0 | P20: =[15]Summary!$N$7 -> - | Q20: =G20+I20+K20 -> 35 | R20: =H20+J20+L20 -> 25 | T20: 35 | U20: 30 | V20: =[15]Summary!$Q$7 -> - | W20: =[15]Summary!$R$7 -> - | Y20: 30 | Z20: 28 | AA20: =[15]Summary!$U$7 -> - | AB20: =[15]Summary!$V$7 -> - | AD20: 25 | AE20: 10 | AF20: =[15]Summary!$Y$7 -> - | AG20: =[15]Summary!$Z$7 -> - | AI20: =[15]Summary!$AA$7 -> 42138 | AJ20: =[15]Summary!$AB$7 -> ? | AK20: =[15]Summary!$AC$7 -> ? | AL20: =[15]Summary!$AD$7 -> ? | AM20: =[15]Summary!$AE$7 -> RTL: POST: FPGA:
B21: 16 | C21: =[16]Summary!$B$7 -> WDT | D21: =[16]Summary!$C$7 -> 안병욱 선임 | E21: =[16]Summary!$D$7 -> 안병욱 선임 | G21: 18 | H21: 10 | I21: 20 | J21: 16 | K21: =[16]Summary!$I$7 -> 0 | L21: =[16]Summary!$J$7 -> 0 | M21: =[16]Summary!$K$7 -> - | N21: =[16]Summary!$L$7 -> 0 | O21: =[16]Summary!$M$7 -> 0 | P21: =[16]Summary!$N$7 -> - | Q21: =G21+I21+K21 -> 38 | R21: =H21+J21+L21 -> 26 | T21: 35 | U21: 30 | V21: =[16]Summary!$Q$7 -> - | W21: =[16]Summary!$R$7 -> - | Y21: 40 | Z21: 32 | AA21: =[16]Summary!$U$7 -> - | AB21: =[16]Summary!$V$7 -> - | AD21: 20 | AE21: 2 | AF21: =[16]Summary!$Y$7 -> - | AG21: =[16]Summary!$Z$7 -> - | AI21: =[16]Summary!$AA$7 -> 42138 | AJ21: =[16]Summary!$AB$7 -> ? | AK21: =[16]Summary!$AC$7 -> ? | AL21: =[16]Summary!$AD$7 -> ? | AM21: =[16]Summary!$AE$7 -> RTL: POST: FPGA:
B22: 17 | C22: =[17]Summary!$B$7 -> UART | D22: =[17]Summary!$C$7 -> 안병욱 선임 | E22: =[17]Summary!$D$7 -> 안병욱 선임 | G22: 17 | H22: 15 | I22: 25 | J22: 20 | K22: =[17]Summary!$I$7 -> 0 | L22: =[17]Summary!$J$7 -> 0 | M22: =[17]Summary!$K$7 -> - | N22: =[17]Summary!$L$7 -> 0 | O22: =[17]Summary!$M$7 -> 0 | P22: =[17]Summary!$N$7 -> - | Q22: =G22+I22+K22 -> 42 | R22: =H22+J22+L22 -> 35 | T22: 25 | U22: 30 | V22: =[17]Summary!$Q$7 -> - | W22: =[17]Summary!$R$7 -> - | Y22: 25 | Z22: 20 | AA22: =[17]Summary!$U$7 -> - | AB22: =[17]Summary!$V$7 -> - | AD22: 30 | AE22: 2 | AF22: =[17]Summary!$Y$7 -> - | AG22: =[17]Summary!$Z$7 -> - | AI22: =[17]Summary!$AA$7 -> 42138 | AJ22: =[17]Summary!$AB$7 -> ? | AK22: =[17]Summary!$AC$7 -> ? | AL22: =[17]Summary!$AD$7 -> ? | AM22: =[17]Summary!$AE$7 -> RTL: POST: FPGA:
B23: 18 | C23: =[18]Summary!$B$7 -> Clock Controller | D23: =[18]Summary!$C$7 -> 김정욱 책임 | E23: =[18]Summary!$D$7 -> 김정욱 책임 | G23: 16 | H23: 15 | I23: 25 | J23: 25 | K23: =[18]Summary!$I$7 -> 0 | L23: =[18]Summary!$J$7 -> 0 | M23: =[18]Summary!$K$7 -> - | N23: =[18]Summary!$L$7 -> 0 | O23: =[18]Summary!$M$7 -> 0 | P23: =[18]Summary!$N$7 -> - | Q23: =G23+I23+K23 -> 41 | R23: =H23+J23+L23 -> 40 | T23: 25 | U23: 20 | V23: =[18]Summary!$Q$7 -> - | W23: =[18]Summary!$R$7 -> - | Y23: 25 | Z23: 25 | AA23: =[18]Summary!$U$7 -> - | AB23: =[18]Summary!$V$7 -> - | AD23: 30 | AE23: 5 | AF23: =[18]Summary!$Y$7 -> - | AG23: =[18]Summary!$Z$7 -> - | AI23: =[18]Summary!$AA$7 -> 42138 | AJ23: =[18]Summary!$AB$7 -> ? | AK23: =[18]Summary!$AC$7 -> ? | AL23: =[18]Summary!$AD$7 -> ? | AM23: =[18]Summary!$AE$7 -> RTL: POST: FPGA:
B24: 19 | C24: =[19]Summary!$B$7 -> Reset Controller | D24: =[19]Summary!$C$7 -> 김정욱 책임 | E24: =[19]Summary!$D$7 -> 김정욱 책임 | G24: 20 | H24: 13 | I24: 25 | J24: 22 | K24: =[19]Summary!$I$7 -> 0 | L24: =[19]Summary!$J$7 -> 0 | M24: =[19]Summary!$K$7 -> - | N24: =[19]Summary!$L$7 -> 0 | O24: =[19]Summary!$M$7 -> 0 | P24: =[19]Summary!$N$7 -> - | Q24: =G24+I24+K24 -> 45 | R24: =H24+J24+L24 -> 35 | T24: 25 | U24: 20 | V24: =[19]Summary!$Q$7 -> - | W24: =[19]Summary!$R$7 -> - | Y24: 25 | Z24: 22 | AA24: =[19]Summary!$U$7 -> - | AB24: =[19]Summary!$V$7 -> - | AD24: 30 | AE24: 8 | AF24: =[19]Summary!$Y$7 -> - | AG24: =[19]Summary!$Z$7 -> - | AI24: =[19]Summary!$AA$7 -> 42138 | AJ24: =[19]Summary!$AB$7 -> ? | AK24: =[19]Summary!$AC$7 -> ? | AL24: =[19]Summary!$AD$7 -> ? | AM24: =[19]Summary!$AE$7 -> RTL: POST: FPGA:
B25: 20 | C25: =[20]Summary!$B$7 -> eFuse Controller | D25: =[20]Summary!$C$7 -> 안병욱 선임 | E25: =[20]Summary!$D$7 -> 안병욱 선임 | G25: 21 | H25: 20 | I25: 25 | J25: 22 | K25: =[20]Summary!$I$7 -> 0 | L25: =[20]Summary!$J$7 -> 0 | M25: =[20]Summary!$K$7 -> - | N25: =[20]Summary!$L$7 -> 0 | O25: =[20]Summary!$M$7 -> 0 | P25: =[20]Summary!$N$7 -> - | Q25: =G25+I25+K25 -> 46 | R25: =H25+J25+L25 -> 42 | T25: 40 | U25: 35 | V25: =[20]Summary!$Q$7 -> - | W25: =[20]Summary!$R$7 -> - | Y25: 25 | Z25: 22 | AA25: =[20]Summary!$U$7 -> - | AB25: =[20]Summary!$V$7 -> - | AD25: 25 | AE25: 9 | AF25: =[20]Summary!$Y$7 -> - | AG25: =[20]Summary!$Z$7 -> - | AI25: =[20]Summary!$AA$7 -> 42138 | AJ25: =[20]Summary!$AB$7 -> ? | AK25: =[20]Summary!$AC$7 -> ? | AL25: =[20]Summary!$AD$7 -> ? | AM25: =[20]Summary!$AE$7 -> RTL: POST: FPGA:
B26: 21 | C26: =[21]Summary!$B$7 -> M-PHY | D26: =[21]Summary!$C$7 -> 이현주 선임 | E26: =[21]Summary!$D$7 -> 이현주 선임 | G26: 25 | H26: 22 | I26: 25 | J26: 23 | K26: =[21]Summary!$I$7 -> 0 | L26: =[21]Summary!$J$7 -> 0 | M26: =[21]Summary!$K$7 -> - | N26: =[21]Summary!$L$7 -> 0 | O26: =[21]Summary!$M$7 -> 0 | P26: =[21]Summary!$N$7 -> - | Q26: =G26+I26+K26 -> 50 | R26: =H26+J26+L26 -> 45 | T26: 40 | U26: 30 | V26: =[21]Summary!$Q$7 -> - | W26: =[21]Summary!$R$7 -> - | Y26: 25 | Z26: 23 | AA26: =[21]Summary!$U$7 -> - | AB26: =[21]Summary!$V$7 -> - | AD26: 25 | AE26: 7 | AF26: =[21]Summary!$Y$7 -> - | AG26: =[21]Summary!$Z$7 -> - | AI26: =[21]Summary!$AA$7 -> 42138 | AJ26: =[21]Summary!$AB$7 -> ? | AK26: =[21]Summary!$AC$7 -> ? | AL26: =[21]Summary!$AD$7 -> ? | AM26: =[21]Summary!$AE$7 -> RTL: POST: FPGA:
B27: 22 | C27: =[22]Summary!$B$7 -> Nand PHY | D27: =[22]Summary!$C$7 -> 이종용 선임 | E27: =[22]Summary!$D$7 -> 이종용 선임 | G27: 20 | H27: 20 | I27: 30 | J27: 25 | K27: =[22]Summary!$I$7 -> 0 | L27: =[22]Summary!$J$7 -> 0 | M27: =[22]Summary!$K$7 -> - | N27: =[22]Summary!$L$7 -> 0 | O27: =[22]Summary!$M$7 -> 0 | P27: =[22]Summary!$N$7 -> - | Q27: =G27+I27+K27 -> 50 | R27: =H27+J27+L27 -> 45 | T27: 35 | U27: 30 | V27: =[22]Summary!$Q$7 -> - | W27: =[22]Summary!$R$7 -> - | Y27: 30 | Z27: 30 | AA27: =[22]Summary!$U$7 -> - | AB27: =[22]Summary!$V$7 -> - | AD27: 30 | AE27: 5 | AF27: =[22]Summary!$Y$7 -> - | AG27: =[22]Summary!$Z$7 -> - | AI27: =[22]Summary!$AA$7 -> 42138 | AJ27: =[22]Summary!$AB$7 -> ? | AK27: =[22]Summary!$AC$7 -> ? | AL27: =[22]Summary!$AD$7 -> ? | AM27: =[22]Summary!$AE$7 -> RTL: POST: FPGA:
B28: 23 | C28: =[23]Summary!$B$7 -> Nand IO | D28: =[23]Summary!$C$7 -> 이종용 선임 | E28: =[23]Summary!$D$7 -> 이종용 선임 | G28: 30 | H28: 25 | I28: 35 | J28: 30 | K28: =[23]Summary!$I$7 -> 0 | L28: =[23]Summary!$J$7 -> 0 | M28: =[23]Summary!$K$7 -> - | N28: =[23]Summary!$L$7 -> 0 | O28: =[23]Summary!$M$7 -> 0 | P28: =[23]Summary!$N$7 -> - | Q28: =G28+I28+K28 -> 65 | R28: =H28+J28+L28 -> 55 | T28: 35 | U28: 30 | V28: =[23]Summary!$Q$7 -> - | W28: =[23]Summary!$R$7 -> - | Y28: 20 | Z28: 18 | AA28: =[23]Summary!$U$7 -> - | AB28: =[23]Summary!$V$7 -> - | AD28: 30 | AE28: 8 | AF28: =[23]Summary!$Y$7 -> - | AG28: =[23]Summary!$Z$7 -> - | AI28: =[23]Summary!$AA$7 -> 42138 | AJ28: =[23]Summary!$AB$7 -> ? | AK28: =[23]Summary!$AC$7 -> ? | AL28: =[23]Summary!$AD$7 -> ? | AM28: =[23]Summary!$AE$7 -> RTL: POST: FPGA:
B29: 24 | C29: =[24]Summary!$B$7 -> Test Mux | D29: =[24]Summary!$C$7 -> 양창호 선임 | E29: =[24]Summary!$D$7 -> 양창호 선임 | G29: 35 | H29: 30 | I29: 20 | J29: 15 | K29: =[24]Summary!$I$7 -> 0 | L29: =[24]Summary!$J$7 -> 0 | M29: =[24]Summary!$K$7 -> - | N29: =[24]Summary!$L$7 -> 0 | O29: =[24]Summary!$M$7 -> 0 | P29: =[24]Summary!$N$7 -> - | Q29: =G29+I29+K29 -> 55 | R29: =H29+J29+L29 -> 45 | T29: 20 | U29: 20 | V29: =[24]Summary!$Q$7 -> - | W29: =[24]Summary!$R$7 -> - | Y29: 30 | Z29: 15 | AA29: =[24]Summary!$U$7 -> - | AB29: =[24]Summary!$V$7 -> - | AD29: 25 | AE29: 2 | AF29: =[24]Summary!$Y$7 -> - | AG29: =[24]Summary!$Z$7 -> - | AI29: =[24]Summary!$AA$7 -> 42138 | AJ29: =[24]Summary!$AB$7 -> ? | AK29: =[24]Summary!$AC$7 -> ? | AL29: =[24]Summary!$AD$7 -> ? | AM29: =[24]Summary!$AE$7 -> RTL: POST: FPGA:
B30: 25 | C30: =[25]Summary!$B$7 -> HW Bypass | D30: =[25]Summary!$C$7 -> 양창호 선임 | E30: =[25]Summary!$D$7 -> 양창호 선임 | G30: 20 | H30: 20 | I30: 25 | J30: 25 | K30: =[25]Summary!$I$7 -> 0 | L30: =[25]Summary!$J$7 -> 0 | M30: =[25]Summary!$K$7 -> - | N30: =[25]Summary!$L$7 -> 0 | O30: =[25]Summary!$M$7 -> 0 | P30: =[25]Summary!$N$7 -> - | Q30: =G30+I30+K30 -> 45 | R30: =H30+J30+L30 -> 45 | T30: 25 | U30: 20 | V30: =[25]Summary!$Q$7 -> - | W30: =[25]Summary!$R$7 -> - | Y30: 25 | Z30: 5 | AA30: =[25]Summary!$U$7 -> - | AB30: =[25]Summary!$V$7 -> - | AD30: 30 | AE30: 2 | AF30: =[25]Summary!$Y$7 -> - | AG30: =[25]Summary!$Z$7 -> - | AI30: =[25]Summary!$AA$7 -> 42138 | AJ30: =[25]Summary!$AB$7 -> ? | AK30: =[25]Summary!$AC$7 -> ? | AL30: =[25]Summary!$AD$7 -> ? | AM30: =[25]Summary!$AE$7 -> RTL: POST: FPGA:
B31: 26 | C31: =[26]Summary!$B$7 -> Analog IP | D31: =[26]Summary!$C$7 -> 양창호 선임 | E31: =[26]Summary!$D$7 -> 양창호 선임 | G31: 20 | H31: 18 | I31: 30 | J31: 30 | K31: =[26]Summary!$I$7 -> 0 | L31: =[26]Summary!$J$7 -> 0 | M31: =[26]Summary!$K$7 -> - | N31: =[26]Summary!$L$7 -> 0 | O31: =[26]Summary!$M$7 -> 0 | P31: =[26]Summary!$N$7 -> - | Q31: =G31+I31+K31 -> 50 | R31: =H31+J31+L31 -> 48 | T31: 30 | U31: 20 | V31: =[26]Summary!$Q$7 -> - | W31: =[26]Summary!$R$7 -> - | Y31: 30 | Z31: 2 | AA31: =[26]Summary!$U$7 -> - | AB31: =[26]Summary!$V$7 -> - | AD31: 40 | AE31: 5 | AF31: =[26]Summary!$Y$7 -> - | AG31: =[26]Summary!$Z$7 -> - | AI31: =[26]Summary!$AA$7 -> 42138 | AJ31: =[26]Summary!$AB$7 -> ? | AK31: =[26]Summary!$AC$7 -> ? | AL31: =[26]Summary!$AD$7 -> ? | AM31: =[26]Summary!$AE$7 -> RTL: POST: FPGA:
B32: 27 | C32: =[27]Summary!$B$7 -> GPIO | D32: =[27]Summary!$C$7 -> 양창호 선임 | E32: =[27]Summary!$D$7 -> 양창호 선임 | G32: 20 | H32: 10 | I32: 40 | J32: 35 | K32: =[27]Summary!$I$7 -> 0 | L32: =[27]Summary!$J$7 -> 0 | M32: =[27]Summary!$K$7 -> - | N32: =[27]Summary!$L$7 -> 0 | O32: =[27]Summary!$M$7 -> 0 | P32: =[27]Summary!$N$7 -> - | Q32: =G32+I32+K32 -> 60 | R32: =H32+J32+L32 -> 45 | T32: 30 | U32: 20 | V32: =[27]Summary!$Q$7 -> - | W32: =[27]Summary!$R$7 -> - | Y32: 20 | Z32: 3 | AA32: =[27]Summary!$U$7 -> - | AB32: =[27]Summary!$V$7 -> - | AD32: 50 | AE32: 2 | AF32: =[27]Summary!$Y$7 -> - | AG32: =[27]Summary!$Z$7 -> - | AI32: =[27]Summary!$AA$7 -> 42138 | AJ32: =[27]Summary!$AB$7 -> ? | AK32: =[27]Summary!$AC$7 -> ? | AL32: =[27]Summary!$AD$7 -> ? | AM32: =[27]Summary!$AE$7 -> RTL: POST: FPGA:
B33: - | C33: =[28]Summary!$B$7 -> End to End | D33: =[28]Summary!$C$7 -> ALL | E33: =[28]Summary!$D$7 -> 조성엽 책임 | G33: 10 | H33: 5 | I33: 10 | J33: =[28]Summary!$H$7 -> 0 | K33: =[28]Summary!$I$7 -> 0 | L33: =[28]Summary!$J$7 -> 0 | M33: =[28]Summary!$K$7 -> - | N33: =[28]Summary!$L$7 -> 0 | O33: =[28]Summary!$M$7 -> 0 | P33: =[28]Summary!$N$7 -> - | Q33: =G33+I33+K33 -> 20 | R33: =H33+J33+L33 -> 5 | T33: 25 | U33: 15 | V33: =[28]Summary!$Q$7 -> - | W33: =[28]Summary!$R$7 -> - | Y33: 25 | Z33: 5 | AA33: =[28]Summary!$U$7 -> - | AB33: =[28]Summary!$V$7 -> - | AD33: 20 | AE33: 5 | AF33: =[28]Summary!$Y$7 -> - | AG33: =[28]Summary!$Z$7 -> - | AI33: =[28]Summary!$AA$7 -> 42138 | AJ33: =[28]Summary!$AB$7 -> ? | AK33: =[28]Summary!$AC$7 -> ? | AL33: =[28]Summary!$AD$7 -> ? | AM33: =[28]Summary!$AE$7 -> RTL: POST: FPGA:
B34: - | C34: =[29]Summary!$B$7 -> Post-Silicon Validation | D34: =[29]Summary!$C$7 -> ALL | E34: =[29]Summary!$D$7 -> ALL
B35: Sub Average | G35: =AVERAGE(G6:G33) -> 18.714286 | H35: =AVERAGE(H6:H33) -> 14.642857 | I35: =AVERAGE(I6:I33) -> 24 | J35: =AVERAGE(J6:J33) -> 19.035714 | K35: =AVERAGE(K6:K33) -> 0 | L35: =AVERAGE(L6:L33) -> 0 | N35: =AVERAGE(N7:N33) -> 0 | O35: =AVERAGE(O6:O33) -> 0 | Q35: =AVERAGE(Q6:Q33) -> 42.714286 | R35: =AVERAGE(R6:R33) -> 33.678571 | T35: =AVERAGE(T6:T33) -> 30.357143 | U35: =AVERAGE(U6:U33) -> 24.678571 | V35: - | Y35: =AVERAGE(Y6:Y33) -> 26.428571 | Z35: =AVERAGE(Z6:Z33) -> 19.357143 | AA35: - | AD35: =AVERAGE(AD6:AD33) -> 26.607143 | AE35: =AVERAGE(AE6:AE33) -> 4.2142857 | AF35: -
B36: Sub Sum | G36: =SUM(G6:G33) -> 524 | H36: =SUM(H6:H33) -> 410 | I36: =SUM(I6:I33) -> 672 | J36: =SUM(J6:J33) -> 533 | K36: =SUM(K6:K33) -> 0 | L36: =SUM(L6:L33) -> 0 | M36: =IF(G36=0, "-", L36/G36) -> 0 | N36: - | O36: - | Q36: =SUM(Q6:Q33) -> 1196 | R36: =SUM(R6:R33) -> 943 | T36: =SUM(T6:T33) -> 850 | U36: =SUM(U6:U33) -> 691 | V36: =IF(T36=0, "-", U36/T36) -> 0.81294118 | Y36: =SUM(Y6:Y33) -> 740 | Z36: =SUM(Z6:Z33) -> 542 | AA36: =IF(Y36=0, "-", Z36/Y36) -> 0.73243243 | AD36: =SUM(AD6:AD33) -> 745 | AE36: =SUM(AE6:AE33) -> 118 | AF36: =IF(AD36=0, "-", AE36/AD36) -> 0.15838926
B37: Total | T37: =G36+T36 -> 1374 | U37: =L36+U36 -> 691 | V37: =IF(T37=0, "-", U37/T37) -> 0.50291121
AI39: 1
AI40: 0.9
AI41: 0.7
AI42: 0.5
...

Sheet Chart 1 - Graph (2)
B2: Columbus Verification Status Summary | AP2: 42138
B3: No. | C3: IP | D3: RTL Designer | E3: Verification Engineer | G3: RTL Sim. | V3: FPGA | AB3: POST Sim. | AH3: ASIC | AN3: Last Updated | AR3: Remark / Coverage Waive
G4: F1 | I4: F2 | K4: F3 | M4: F1~3 | N4: Cov. SoC (F2,F3) | O4: Cov. S.A (F0,F1) | P4: Done | S4: Prog. | V4: Cases | W4: Pass | X4: Prog. | Z4: Done | AB4: Cases | AC4: Pass | AD4: Prog. | AE4: Done | AH4: Cases | AI4: Pass | AJ4: Prog. | AL4: Done | AN4: Date | AO4: RTL | AP4: FPGA | AQ4: ASIC
C5: IP | G5: Cases | H5: Pass | I5: Cases | J5: Pass | K5: Cases | L5: Pass | M5: Prog. | Q5: RTL Case | R5: RTL Pass | S5: % | V5: FPGA Case | W5: FPGA Pass | X5: % | AB5: Sim. Case | AC5: Sim. Pass | AH5: ASIC Case | AI5: ASIC Pass
B6: 1 | C6: =[1]Summary!$B$7 -> Cortex-M3 | D6: =[1]Summary!$C$7 -> 최호윤 수석 | E6: =[1]Summary!$D$7 -> 조성엽 책임 | G6: 10 | H6: 10 | I6: 12 | J6: 5 | K6: =[1]Summary!$I$7 -> 0 | L6: =[1]Summary!$J$7 -> 0 | M6: =[1]Summary!$K$7 -> - | N6: =[1]Summary!$L$7 -> 0 | O6: =[1]Summary!$M$7 -> 0 | P6: =[1]Summary!$N$7 -> - | Q6: =G6+I6+K6 -> 22 | R6: =H6+J6+L6 -> 15 | S6: =R6/Q6 -> 0.68181818 | V6: 30 | W6: 26 | X6: =W6/V6 -> 0.86666667 | Z6: =[1]Summary!$R$7 -> - | AB6: 20 | AC6: 10 | AD6: =AC6/AB6 -> 0.5 | AE6: =[1]Summary!$V$7 -> - | AH6: 20 | AI6: 5 | AJ6: =AI6/AH6 -> 0.25 | AL6: =[1]Summary!$Z$7 -> - | AN6: =[1]Summary!$AA$7 -> 42138 | AO6: =[1]Summary!$AB$7 -> ? | AP6: =[1]Summary!$AC$7 -> ? | AQ6: =[1]Summary!$AD$7 -> ? | AR6: =[1]Summary!$AE$7 -> RTL: POST: FPGA:
B7: 2 | C7: =[2]Summary!$B$7 -> HCT | D7: =[2]Summary!$C$7 -> 이원규 선임 | E7: =[2]Summary!$D$7 -> 박재우 책임 | G7: 15 | H7: 5 | I7: 12 | J7: 5 | K7: =[2]Summary!$I$7 -> 0 | L7: =[2]Summary!$J$7 -> 0 | M7: =[2]Summary!$K$7 -> - | N7: =[2]Summary!$L$7 -> 0 | O7: =[2]Summary!$M$7 -> 0 | P7: =[2]Summary!$N$7 -> - | Q7: =G7+I7+K7 -> 27 | R7: =H7+J7+L7 -> 10 | S7: =R7/Q7 -> 0.37037037 | V7: 40 | W7: 25 | X7: =W7/V7 -> 0.625 | Z7: =[2]Summary!$R$7 -> - | AB7: 30 | AC7: 20 | AD7: =AC7/AB7 -> 0.66666667 | AE7: =[2]Summary!$V$7 -> - | AH7: 30 | AI7: 2 | AJ7: =AI7/AH7 -> 0.066666667 | AL7: =[2]Summary!$Z$7 -> - | AN7: =[2]Summary!$AA$7 -> 42138 | AO7: =[2]Summary!$AB$7 -> ? | AP7: =[2]Summary!$AC$7 -> ? | AQ7: =[2]Summary!$AD$7 -> ? | AR7: =[2]Summary!$AE$7 -> RTL: POST: FPGA:
B8: 3 | C8: =[3]Summary!$B$7 -> FCT | D8: =[3]Summary!$C$7 -> 천동엽 책임 | E8: =[3]Summary!$D$7 -> 조성엽 책임 | G8: 20 | H8: 18 | I8: 20 | J8: 15 | K8: =[3]Summary!$I$7 -> 0 | L8: =[3]Summary!$J$7 -> 0 | M8: =[3]Summary!$K$7 -> - | N8: =[3]Summary!$L$7 -> 0 | O8: =[3]Summary!$M$7 -> 0 | P8: =[3]Summary!$N$7 -> - | Q8: =G8+I8+K8 -> 40 | R8: =H8+J8+L8 -> 33 | S8: =R8/Q8 -> 0.825 | V8: 30 | W8: 30 | X8: =W8/V8 -> 1 | Z8: =[3]Summary!$R$7 -> - | AB8: 30 | AC8: 25 | AD8: =AC8/AB8 -> 0.83333333 | AE8: =[3]Summary!$V$7 -> - | AH8: 30 | AI8: 3 | AJ8: =AI8/AH8 -> 0.1 | AL8: =[3]Summary!$Z$7 -> - | AN8: =[3]Summary!$AA$7 -> 42138 | AO8: =[3]Summary!$AB$7 -> ? | AP8: =[3]Summary!$AC$7 -> ? | AQ8: =[3]Summary!$AD$7 -> ? | AR8: =[3]Summary!$AE$7 -> RTL: POST: FPGA:
B9: 4 | C9: =[4]Summary!$B$7 -> Buffer Manager | D9: =[4]Summary!$C$7 -> 지대근 책임 | E9: =[4]Summary!$D$7 -> 조성엽 책임 | G9: 15 | H9: 10 | I9: 30 | J9: 20 | K9: =[4]Summary!$I$7 -> 0 | L9: =[4]Summary!$J$7 -> 0 | M9: =[4]Summary!$K$7 -> - | N9: =[4]Summary!$L$7 -> 0 | O9: =[4]Summary!$M$7 -> 0 | P9: =[4]Summary!$N$7 -> - | Q9: =G9+I9+K9 -> 45 | R9: =H9+J9+L9 -> 30 | S9: =R9/Q9 -> 0.66666667 | V9: 20 | W9: 20 | X9: =W9/V9 -> 1 | Z9: =[4]Summary!$R$7 -> - | AB9: 40 | AC9: 30 | AD9: =AC9/AB9 -> 0.75 | AE9: =[4]Summary!$V$7 -> - | AH9: 30 | AI9: 2 | AJ9: =AI9/AH9 -> 0.066666667 | AL9: =[4]Summary!$Z$7 -> - | AN9: =[4]Summary!$AA$7 -> 42138 | AO9: =[4]Summary!$AB$7 -> ? | AP9: =[4]Summary!$AC$7 -> ? | AQ9: =[4]Summary!$AD$7 -> ? | AR9: =[4]Summary!$AE$7 -> RTL: POST: FPGA:
B10: 5 | C10: =[5]Summary!$B$7 -> Search Engine | D10: =[5]Summary!$C$7 -> 김현욱 선임 | E10: =[5]Summary!$D$7 -> 김현욱 선임 | G10: 20 | H10: 16 | I10: 15 | J10: 10 | K10: =[5]Summary!$I$7 -> 0 | L10: =[5]Summary!$J$7 -> 0 | M10: =[5]Summary!$K$7 -> - | N10: =[5]Summary!$L$7 -> 0 | O10: =[5]Summary!$M$7 -> 0 | P10: =[5]Summary!$N$7 -> - | Q10: =G10+I10+K10 -> 35 | R10: =H10+J10+L10 -> 26 | S10: =R10/Q10 -> 0.74285714 | V10: 20 | W10: 20 | X10: =W10/V10 -> 1 | Z10: =[5]Summary!$R$7 -> - | AB10: 20 | AC10: 15 | AD10: =AC10/AB10 -> 0.75 | AE10: =[5]Summary!$V$7 -> - | AH10: 30 | AI10: 2 | AJ10: =AI10/AH10 -> 0.066666667 | AL10: =[5]Summary!$Z$7 -> - | AN10: =[5]Summary!$AA$7 -> 42138 | AO10: =[5]Summary!$AB$7 -> ? | AP10: =[5]Summary!$AC$7 -> ? | AQ10: =[5]Summary!$AD$7 -> ? | AR10: =[5]Summary!$AE$7 -> RTL: POST: FPGA:
B11: 6 | C11: =[6]Summary!$B$7 -> MTSE | D11: =[6]Summary!$C$7 -> 김현욱 선임 | E11: =[6]Summary!$D$7 -> 김현욱 선임 | G11: 15 | H11: 14 | I11: 20 | J11: 15 | K11: =[6]Summary!$I$7 -> 0 | L11: =[6]Summary!$J$7 -> 0 | M11: =[6]Summary!$K$7 -> - | N11: =[6]Summary!$L$7 -> 0 | O11: =[6]Summary!$M$7 -> 0 | P11: =[6]Summary!$N$7 -> - | Q11: =G11+I11+K11 -> 35 | R11: =H11+J11+L11 -> 29 | S11: =R11/Q11 -> 0.82857143 | V11: 30 | W11: 25 | X11: =W11/V11 -> 0.83333333 | Z11: =[6]Summary!$R$7 -> - | AB11: 20 | AC11: 15 | AD11: =AC11/AB11 -> 0.75 | AE11: =[6]Summary!$V$7 -> - | AH11: 30 | AI11: 4 | AJ11: =AI11/AH11 -> 0.13333333 | AL11: =[6]Summary!$Z$7 -> - | AN11: =[6]Summary!$AA$7 -> 42138 | AO11: =[6]Summary!$AB$7 -> ? | AP11: =[6]Summary!$AC$7 -> ? | AQ11: =[6]Summary!$AD$7 -> ? | AR11: =[6]Summary!$AE$7 -> RTL: POST: FPGA:
B12: 7 | C12: =[7]Summary!$B$7 -> System Memory | D12: =[7]Summary!$C$7 -> 김현욱 선임 | E12: =[7]Summary!$D$7 -> 김현욱 선임 | G12: 10 | H12: 8 | I12: 15 | J12: 12 | K12: =[7]Summary!$I$7 -> 0 | L12: =[7]Summary!$J$7 -> 0 | M12: =[7]Summary!$K$7 -> - | N12: =[7]Summary!$L$7 -> 0 | O12: =[7]Summary!$M$7 -> 0 | P12: =[7]Summary!$N$7 -> - | Q12: =G12+I12+K12 -> 25 | R12: =H12+J12+L12 -> 20 | S12: =R12/Q12 -> 0.8 | V12: 30 | W12: 20 | X12: =W12/V12 -> 0.66666667 | Z12: =[7]Summary!$R$7 -> - | AB12: 20 | AC12: 20 | AD12: =AC12/AB12 -> 1 | AE12: =[7]Summary!$V$7 -> - | AH12: 20 | AI12: 3 | AJ12: =AI12/AH12 -> 0.15 | AL12: =[7]Summary!$Z$7 -> - | AN12: =[7]Summary!$AA$7 -> 42138 | AO12: =[7]Summary!$AB$7 -> ? | AP12: =[7]Summary!$AC$7 -> ? | AQ12: =[7]Summary!$AD$7 -> ? | AR12: =[7]Summary!$AE$7 -> RTL: POST: FPGA:
B13: 8 | C13: =[8]Summary!$B$7 -> Data Buffer | D13: =[8]Summary!$C$7 -> 김현욱 선임 | E13: =[8]Summary!$D$7 -> 김현욱 선임 | G13: 8 | H13: 8 | I13: 18 | J13: 15 | K13: =[8]Summary!$I$7 -> 0 | L13: =[8]Summary!$J$7 -> 0 | M13: =[8]Summary!$K$7 -> - | N13: =[8]Summary!$L$7 -> 0 | O13: =[8]Summary!$M$7 -> 0 | P13: =[8]Summary!$N$7 -> - | Q13: =G13+I13+K13 -> 26 | R13: =H13+J13+L13 -> 23 | S13: =R13/Q13 -> 0.88461538 | V13: 40 | W13: 35 | X13: =W13/V13 -> 0.875 | Z13: =[8]Summary!$R$7 -> - | AB13: 20 | AC13: 18 | AD13: =AC13/AB13 -> 0.9 | AE13: =[8]Summary!$V$7 -> - | AH13: 20 | AI13: 4 | AJ13: =AI13/AH13 -> 0.2 | AL13: =[8]Summary!$Z$7 -> - | AN13: =[8]Summary!$AA$7 -> 42138 | AO13: =[8]Summary!$AB$7 -> ? | AP13: =[8]Summary!$AC$7 -> ? | AQ13: =[8]Summary!$AD$7 -> ? | AR13: =[8]Summary!$AE$7 -> RTL: POST: FPGA:
B14: 9 | C14: =[9]Summary!$B$7 -> DMA | D14: =[9]Summary!$C$7 -> 김현욱 선임 | E14: =[9]Summary!$D$7 -> 김현욱 선임 | G14: 9 | H14: 8 | I14: 30 | J14: 20 | K14: =[9]Summary!$I$7 -> 0 | L14: =[9]Summary!$J$7 -> 0 | M14: =[9]Summary!$K$7 -> - | N14: =[9]Summary!$L$7 -> 0 | O14: =[9]Summary!$M$7 -> 0 | P14: =[9]Summary!$N$7 -> - | Q14: =G14+I14+K14 -> 39 | R14: =H14+J14+L14 -> 28 | S14: =R14/Q14 -> 0.71794872 | V14: 50 | W14: 40 | X14: =W14/V14 -> 0.8 | Z14: =[9]Summary!$R$7 -> - | AB14: 20 | AC14: 20 | AD14: =AC14/AB14 -> 1 | AE14: =[9]Summary!$V$7 -> - | AH14: 20 | AI14: 2 | AJ14: =AI14/AH14 -> 0.1 | AL14: =[9]Summary!$Z$7 -> - | AN14: =[9]Summary!$AA$7 -> 42138 | AO14: =[9]Summary!$AB$7 -> ? | AP14: =[9]Summary!$AC$7 -> ? | AQ14: =[9]Summary!$AD$7 -> ? | AR14: =[9]Summary!$AE$7 -> RTL: POST: FPGA:
B15: 10 | C15: =[10]Summary!$B$7 -> Back Bone | D15: =[10]Summary!$C$7 -> 최호윤 수석 | E15: =[10]Summary!$D$7 -> 최호윤 수석 | G15: 30 | H15: 10 | I15: 30 | J15: 25 | K15: =[10]Summary!$I$7 -> 0 | L15: =[10]Summary!$J$7 -> 0 | M15: =[10]Summary!$K$7 -> - | N15: =[10]Summary!$L$7 -> 0 | O15: =[10]Summary!$M$7 -> 0 | P15: =[10]Summary!$N$7 -> - | Q15: =G15+I15+K15 -> 60 | R15: =H15+J15+L15 -> 35 | S15: =R15/Q15 -> 0.58333333 | V15: 20 | W15: 20 | X15: =W15/V15 -> 1 | Z15: =[10]Summary!$R$7 -> - | AB15: 20 | AC15: 15 | AD15: =AC15/AB15 -> 0.75 | AE15: =[10]Summary!$V$7 -> - | AH15: 20 | AI15: 5 | AJ15: =AI15/AH15 -> 0.25 | AL15: =[10]Summary!$Z$7 -> - | AN15: =[10]Summary!$AA$7 -> 42138 | AO15: =[10]Summary!$AB$7 -> ? | AP15: =[10]Summary!$AC$7 -> ? | AQ15: =[10]Summary!$AD$7 -> ? | AR15: =[10]Summary!$AE$7 -> RTL: POST: FPGA:
B16: 11 | C16: =[11]Summary!$B$7 -> System Controller | D16: =[11]Summary!$C$7 -> 김정욱 책임 | E16: =[11]Summary!$D$7 -> 김정욱 책임 | G16: 20 | H16: 18 | I16: 30 | J16: 22 | K16: =[11]Summary!$I$7 -> 0 | L16: =[11]Summary!$J$7 -> 0 | M16: =[11]Summary!$K$7 -> - | N16: =[11]Summary!$L$7 -> 0 | O16: =[11]Summary!$M$7 -> 0 | P16: =[11]Summary!$N$7 -> - | Q16: =G16+I16+K16 -> 50 | R16: =H16+J16+L16 -> 40 | S16: =R16/Q16 -> 0.8 | V16: 30 | W16: 15 | X16: =W16/V16 -> 0.5 | Z16: =[11]Summary!$R$7 -> - | AB16: 35 | AC16: 30 | AD16: =AC16/AB16 -> 0.85714286 | AE16: =[11]Summary!$V$7 -> - | AH16: 15 | AI16: 2 | AJ16: =AI16/AH16 -> 0.13333333 | AL16: =[11]Summary!$Z$7 -> - | AN16: =[11]Summary!$AA$7 -> 42138 | AO16: =[11]Summary!$AB$7 -> ? | AP16: =[11]Summary!$AC$7 -> ? | AQ16: =[11]Summary!$AD$7 -> ? | AR16: =[11]Summary!$AE$7 -> RTL: POST: FPGA:
